Workbook

Sheet Cover
B2: FADM Group Assignment — Part 1
B4: Target Company: | C4: Adani Power Ltd (NSE: ADANIPOWER, BSE: 533096)
B5: Competitors: | C5: Tata Power Company Ltd (NSE: TATAPOWER) | Torrent Power Ltd (NSE: TORNTPOWER)
B6: Sector: | C6: Power Generation, Transmission & Distribution (India)
B7: Group / Student: | C7: [FILL IN: Group-X / Student Name]
B8: Date prepared: | C8: 15 July 2026
B10: Contents
B11: FS Extracts — financial-statement trail (course requirement)
B12: 1. Business Overview & Market
B13: 2. Sales / Asset / Profit / Market-Price Growth (5-yr) — Comparison & Chart
B14: 3. Sales per Rupee of Asset & Sales per Employee
B15: 4. Business Acquisitions & Post-Acquisition Impact
B16: 5. Shareholding Pattern (Promoters, FII, DII/MF, Pledge, Free Float)
B17: 6. Reportable Business Segments — 5-yr Trend & Comparison
B18: 7. Group Structure — Subsidiaries
B19: 8. Associates & Joint Ventures
B20: 9. Other Investments (ex subs/associates/JVs) up to FY23
B21: 10. Major Changes in Financing (5-yr)
... B37: (replaces earlier draft sheets that mixed in mislabeled standalone Adani Power data)

Sheet FS_Extracts
A1: Financial Statement Extracts (Consolidated), FY22-FY26
A2: Key lines from each company's audited Consolidated Financial Statements, extracted from the Annual Report PDFs stored in this repository. These are the 'trail' for every figure used in Sheets 2, 3 and 6.
A5: ADANI POWER LIMITED
A6: Line item (₹ crore, consolidated) | B6: FY22 | C6: FY23 | D6: FY24 | E6: FY25 | F6: FY26
A7: Revenue from Operations | B7: 27711.18 | C7: 38773.3 | D7: 50351.25 | E7: 56203.09 | F7: 54240.52
A8: Total Income | B8: 31686.47 | C8: 43040.52 | D8: 60281.48 | E8: 58905.83 | F8: 57865.28
A9: Profit Before Tax (before deferred tax adj.) | B9: 6577.13 | C9: 7674.7 | D9: 20791.51 | E9: 16359.51 | F9: 15499.51
A10: Total Tax Expense / (Credit) | B10: 1744.8 | C10: -3267.37 | D10: -37.28 | E10: 3609.9 | F10: 2528.43
A11: Profit for the Year (PAT) | B11: 4911.58 | C11: 10726.64 | D11: 20828.79 | E11: 12749.61 | F11: 12971.08
A12: Total Assets | B12: 81981.02 | C12: 85821.27 | D12: 92324.77 | E12: 112917.57 | F12: 142279.92
A13: Source PDFs in repo: AR_22088_ADANIPOWER_2022_2023 (FY22 & FY23), AR_24072_ADANIPOWER_2023_2024 (FY24), ADANIPOWER-2025 / AR_26476 (FY25), AR_29298_ADANIPOWER_2025_2026 (FY26) — Consolidated Statement of P&L and Balance Sheet.
A15: THE TATA POWER COMPANY LIMITED
A16: Line item (₹ crore, consolidated) | B16: FY22 | C16: FY23 | D16: FY24 | E16: FY25 | F16: FY26
A17: Revenue from Operations (as reported P&L) | B17: 42815.67 | C17: 55109.08 | D17: N/A | E17: 65478.24 | F17: N/A
A18: Total Income (highlights basis, incl. regulatory) | B18: 42576 | C18: 56033 | D18: 63272.32 | E18: 66992.17 | F18: 64171.66
A19: Profit for the Year (PAT, reported) | B19: 2156 | C19: 3810 | D19: 4280 | E19: 4775 | F19: 5118
A20: Total Assets | B20: 112884.59 | C20: 128349.04 | D20: 139553.49 | E20: 156711.29 | F20: 175171.78
A21: Source PDFs in repo: AR_20052_TATAPOWER_2021_2022 (FY22), AR_2022_2023 (FY23), AR_24164_TATAPOWER_2023_2024 (FY24), AR_26536 (FY25), AR_29380 (FY26) — Consolidated Statement of P&L and Balance Sheet.
A23: TORRENT POWER LIMITED
A24: Line item (₹ crore, consolidated) | B24: FY22 | C24: FY23 | D24: FY24 | E24: FY25 | F24: FY26
A25: Total Income | B25: 14492.65 | C25: 26075.97 | D25: 27527.53 | E25: 29652.47 | F25: 29288.92
A26: Profit for the Year (PAT) | B26: 458.7 | C26: 2164.67 | D26: 1896 | E26: 3058.61 | F26: 2469.36
A27: Total Assets | B27: 25022.7 | C27: 29910.18 | D27: 33392.48 | E27: 36573.38 | F27: 45193.28
A28: Source PDFs in repo: AR_20392_TORNTPOWER_2021_2022 (FY22), AR_22356 (FY23), AR_24323 (FY24), AR_26840 (FY25), AR_29704 (FY26) — Consolidated Statement of P&L and Balance Sheet.
A30: Trail note
A31: Every Revenue/Total Income, PAT and Total Assets figure in Sheet 2 equals the corresponding line above; Sheet 3 ratios are formulas over Sheet 2 cells; Sheet 6 segment figures come from the Segment Reporting (Ind AS 108) note of the same consolidated financial statements. The full audited financial statements are contained in the Annual Report PDFs submitted alongside this workbook in the same repository/folder, satisfying the course requirement that the file contain the financial statements with calculation trails.

Sheet 1_Business_Overview
A1: 1. Business Overview & Market
A2: Products/services and market in which each company operates
B5: Adani Power Ltd (Target) | C5: Tata Power Company Ltd (Competitor) | D5: Torrent Power Ltd (Competitor)
A6: Positioning | B6: India's largest PRIVATE thermal (base-load) power producer; part of the Adani Group. | C6: India's largest vertically integrated power company (generation + transmission + distribution). | D6: Leading integrated power utility; part of Torrent Group (also pharma & city-gas distribution).
A7: Core products/services | B7: Thermal power generation (subcritical to ultra-supercritical); sold via long-term & short-term PPAs and merchant sales on power exchanges. | C7: Generation (thermal+hydro), Transmission, Distribution (regulated discoms); shifting toward 100% renewable generation; new-age products (solar rooftop, EV charging). | D7: Generation (gas, coal, solar, wind), Transmission (~1,340 ckm HV lines), Distribution (licensed + franchise).
A8: Market / geographic footprint | B8: 12 plants across 8 states (Gujarat, Maharashtra, Karnataka, Rajasthan, Chhattisgarh, MP, Jharkhand, Tamil Nadu); ~7.3% of India's coal-based generation capacity; exports power to Bangladesh via Godda plant. | C8: Pan-India: Mumbai & Delhi discoms, 4 Odisha discoms, Ajmer discom; ~12.6 million distribution customers; renewable assets nationwide; expanding into Bhutan hydro & nuclear. | D8: Gujarat (Ahmedabad, Surat, Dahej), Dadra & Nagar Haveli/Daman & Diu, franchise areas Agra (UP) & Bhiwandi (Maharashtra); ~4.3 million customers p.a.
A9: Installed capacity (approx., 2025-26) | B9: ~18,150 MW (post Vidarbha acquisition, Jul 2025), all thermal. | C9: ~11.6 GW renewable identified/under TPREL alone + thermal (Mundra 4 GW+) + hydro + distribution licenses covering 12.6mn customers. | D9: ~2,730 MW gas + 362 MW coal + ~663 MW solar + ~1,220 MW wind (as of FY23/Jan-24 disclosures); Nabha Power (2x700MW coal) added June 2026.
A10: Strategic direction | B10: Capacity expansion via IBC/CIRP acquisitions (Mahan, Korba, Moxie, Vidarbha, JPVL); new Assam UMPP (3,200 MW, ~₹48,000 cr); entry into nuclear power (Adani Atomic Energy Ltd, Feb 2026); Bhutan hydro JV with Druk Green. | C10: Targeting ₹1 lakh crore revenue & ₹10,000 cr PAT by 2030; nuclear, battery storage, solar manufacturing (Odisha); pumped hydro storage (Bhivpuri, Shirawta); Bhutan hydro portfolio (5,033 MW identified). | D10: ₹80,000 crore 5-yr capex plan: +3 GW thermal (incl. Nabha), ~3.96 GW renewables, ~3 GW pumped storage; exploring Green Hydrogen/Ammonia.

Sheet 2_Growth_Comparison
A1: 2. Growth Comparison: Sales, Assets, Profit, Market Price (FY22-FY26, last 5 years)
A2: ₹ crore, Consolidated. All columns VERIFIED from the audited Annual Reports in the repo. Yellow = still needs data.
A5: Company / Metric | B5: FY22 | C5: FY23 | D5: FY24 | E5: FY25 | F5: FY26 | G5: 4-yr CAGR
A7: Adani Power — Revenue / Total Income (₹ cr) | B7: 31686.47 | C7: 43040.52 | D7: 60281.48 | E7: 58905.83 | F7: 57865.28 | G7: =IFERROR(IF(OR(B7="N/A",F7="N/A"),"N/A",(F7/B7)^(1/4)-1),"N/A")
A8: Adani Power — Net Profit / PAT (₹ cr) | B8: 4911.58 | C8: 10726.64 | D8: 20828.79 | E8: 12749.61 | F8: 12971.08 | G8: =IFERROR(IF(OR(B8="N/A",F8="N/A"),"N/A",(F8/B8)^(1/4)-1),"N/A")
A9: Adani Power — Total Assets (₹ cr) | B9: 81981.02 | C9: 85821.27 | D9: 92324.77 | E9: 112917.57 | F9: 142279.92 | G9: =IFERROR(IF(OR(B9="N/A",F9="N/A"),"N/A",(F9/B9)^(1/4)-1),"N/A")
A10: Adani Power — Employees (#) | B10: N/A | C10: 2805 | D10: N/A | E10: 4210 | F10: 3967 | G10: =IFERROR(IF(OR(B10="N/A",F10="N/A"),"N/A",(F10/B10)^(1/4)-1),"N/A")
A11: All figures VERIFIED from Adani Power's audited Integrated Annual Reports (consolidated). Employees = STANDALONE permanent employees on Company rolls; FY22 and FY24 counts not disclosed in the reports available (the FY21-22 Annual Report is not in the repo). FY24 PAT (₹20,829cr) was inflated by one-off other income (₹9,781cr incl. prior-period revenue recognition) vs FY25's normalised ₹12,750cr.
A13: Tata Power — Revenue / Total Income (₹ cr) | B13: 42576 | C13: 56033 | D13: 63272.32 | E13: 66992.17 | F13: 64171.66 | G13: =IFERROR(IF(OR(B13="N/A",F13="N/A"),"N/A",(F13/B13)^(1/4)-1),"N/A")
A14: Tata Power — Net Profit / PAT (₹ cr) | B14: 2156 | C14: 3810 | D14: 4280 | E14: 4775 | F14: 5118 | G14: =IFERROR(IF(OR(B14="N/A",F14="N/A"),"N/A",(F14/B14)^(1/4)-1),"N/A")
A15: Tata Power — Total Assets (₹ cr) | B15: 112884.59 | C15: 128349.04 | D15: 139553.49 | E15: 156711.29 | F15: 175171.78 | G15: =IFERROR(IF(OR(B15="N/A",F15="N/A"),"N/A",(F15/B15)^(1/4)-1),"N/A")
A16: Tata Power — Employees (#) | B16: 2815 | C16: 3071 | D16: N/A | E16: 3130 | F16: 3295 | G16: =IFERROR(IF(OR(B16="N/A",F16="N/A"),"N/A",(F16/B16)^(1/4)-1),"N/A")
A17: All figures VERIFIED from Tata Power's Integrated Annual Reports (consolidated, reported basis). Revenue FY22-23 (42,576/56,033) is the company's own highlights-basis series incl. regulatory income; as-reported P&L 'Revenue from Operations' is slightly lower (42,816/55,109). Employees = STANDALONE parent only (~2,800-3,300) — most of the group workforce sits in subsidiaries (TPREL, discoms), so do not compare with consolidated revenue.
A19: Torrent Power — Revenue / Total Income (₹ cr) | B19: 14492.65 | C19: 26075.97 | D19: 27527.53 | E19: 29652.47 | F19: 29288.92 | G19: =IFERROR(IF(OR(B19="N/A",F19="N/A"),"N/A",(F19/B19)^(1/4)-1),"N/A")
A20: Torrent Power — Net Profit / PAT (₹ cr) | B20: 458.7 | C20: 2164.67 | D20: 1896 | E20: 3058.61 | F20: 2469.36 | G20: =IFERROR(IF(OR(B20="N/A",F20="N/A"),"N/A",(F20/B20)^(1/4)-1),"N/A")
A21: Torrent Power — Total Assets (₹ cr) | B21: 25022.7 | C21: 29910.18 | D21: 33392.48 | E21: 36573.38 | F21: 45193.28 | G21: =IFERROR(IF(OR(B21="N/A",F21="N/A"),"N/A",(F21/B21)^(1/4)-1),"N/A")
A22: Torrent Power — Employees (#) | B22: 7603 | C22: 6992 | D22: 6987 | E22: 7213 | F22: 6687 | G22: =IFERROR(IF(OR(B22="N/A",F22="N/A"),"N/A",(F22/B22)^(1/4)-1),"N/A")
A23: All figures VERIFIED from Torrent Power's Integrated Annual Reports (consolidated). FY22 PAT (₹458.70cr) was depressed by a ~₹1,300cr DGEN plant impairment — treat FY22-base growth rates with care. Employees = standalone permanent employees on Company rolls (Rule 5(1) disclosure) — Torrent runs most operations in the parent entity, so this series is closer to a true group headcount than Adani/Tata's standalone counts.
A25: Market price per share (₹, year-end 31-Mar)
A26: Adani Power — Year-end share price | B26: TO FILL | C26: TO FILL | D26: TO FILL | E26: TO FILL | F26: TO FILL
A27: Tata Power — Year-end share price | B27: TO FILL | C27: TO FILL | D27: TO FILL | E27: TO FILL | F27: TO FILL
A28: Torrent Power — Year-end share price | B28: TO FILL | C28: TO FILL | D28: TO FILL | E28: TO FILL | F28: TO FILL
A30: Comments
A31: SALES GROWTH (FY22→FY26): Adani Power grew revenue ~83% (₹31,686cr → ₹57,865cr, ~16% CAGR), driven by IBC acquisitions (Mahan, Korba) and tariff/prior-period recoveries in FY23-FY24, before plateauing in FY25-FY26. Torrent Power doubled revenue (₹14,493cr → ₹29,289cr, ~19% CAGR) with the single biggest step in FY23 (+80%) from the DNH&DD discom takeover and merchant gas sales. Tata Power grew ~51% (₹42,576cr → ₹64,172cr, ~11% CAGR). PROFIT GROWTH: Adani Power PAT rose from ₹4,912cr to ₹12,971cr (~27% CAGR); FY24's ₹20,829cr spike was one-off-boosted and FY25/FY26 is the cleaner run-rate. Tata Power compounded PAT steadily every single year (₹2,156cr → ₹5,118cr, ~24% CAGR) — the most consistent grower. Torrent is profitable but lumpy: FY22 was impairment-depressed (₹459cr), rebounding to ₹2,165-3,059cr, easing to ₹2,469cr in FY26. ASSETS GROWTH: Adani Power's asset base grew ~74% (₹81,981cr → ₹1,42,280cr), accelerating sharply after FY24 as acquisitions and new capacity landed. Tata Power grew ~55% to ₹1,75,172cr — the largest absolute base. Torrent grew ~81% (₹25,023cr → ₹45,193cr; Nabha Power + capex cycle) — the fastest in relative terms. MARKET PRICE: year-end share-price rows still need NSE/Yahoo historical data (yellow) to complete the fourth lens.

Sheet 2b_Growth_Chart_Data
A1: Year | B1: Adani Power Revenue | C1: Tata Power Revenue | D1: Torrent Power Revenue
A2: FY22 | B2: 31686.47 | C2: 42576 | D2: 14492.65
A3: FY23 | B3: 43040.52 | C3: 56033 | D3: 26075.97
A4: FY24 | B4: 60281.48 | C4: 63272.32 | D4: 27527.53
A5: FY25 | B5: 58905.83 | C5: 66992.17 | D5: 29652.47
A6: FY26 | B6: 57865.28 | C6: 64171.66 | D6: 29288.92
A8: Year | B8: Adani Power PAT | C8: Tata Power PAT | D8: Torrent Power PAT
A9: FY22 | B9: 4911.58 | C9: 2156 | D9: 458.7
A10: FY23 | B10: 10726.64 | C10: 3810 | D10: 2164.67
A11: FY24 | B11: 20828.79 | C11: 4280 | D11: 1896
A12: FY25 | B12: 12749.61 | C12: 4775 | D12: 3058.61
A13: FY26 | B13: 12971.08 | C13: 5118 | D13: 2469.36
A15: Year | B15: Adani Power Assets | C15: Tata Power Assets | D15: Torrent Power Assets
A16: FY22 | B16: 81981.02 | C16: 112884.59 | D16: 25022.7
A17: FY23 | B17: 85821.27 | C17: 128349.04 | D17: 29910.18
A18: FY24 | B18: 92324.77 | C18: 139553.49 | D18: 33392.48
A19: FY25 | B19: 112917.57 | C19: 156711.29 | D19: 36573.38
A20: FY26 | B20: 142279.92 | C20: 175171.78 | D20: 45193.28

Sheet 3_Sales_per_Asset_Employee
A1: 3. Sales per Rupee of Asset Deployed & Sales per Employee (FY22-FY26)
A2: Sales per ₹ of asset = Revenue / Total Assets (x). Sales per employee = Revenue (₹ cr) / Employees, shown in ₹ lakh/employee.
A5: Company / Metric | B5: FY22 | C5: FY23 | D5: FY24 | E5: FY25 | F5: FY26
A7: Adani Power — Sales / Total Assets (x) | B7: =IFERROR(IF(OR(ISTEXT('2_Growth_Comparison'!B7),ISTEXT('2_Growth_Comparison'!B9)),"N/A",'2_Growth_Comparison'!B7/'2_Growth_Comparison'!B9),"N/A") | C7: =IFERROR(IF(OR(ISTEXT('2_Growth_Comparison'!C7),ISTEXT('2_Growth_Comparison'!C9)),"N/A",'2_Growth_Comparison'!C7/'2_Growth_Comparison'!C9),"N/A") | D7: =IFERROR(IF(OR(ISTEXT('2_Growth_Comparison'!D7),ISTEXT('2_Growth_Comparison'!D9)),"N/A",'2_Growth_Comparison'!D7/'2_Growth_Comparison'!D9),"N/A") | E7: =IFERROR(IF(OR(ISTEXT('2_Growth_Comparison'!E7),ISTEXT('2_Growth_Comparison'!E9)),"N/A",'2_Growth_Comparison'!E7/'2_Growth_Comparison'!E9),"N/A") | F7: =IFERROR(IF(OR(ISTEXT('2_Growth_Comparison'!F7),ISTEXT('2_Growth_Comparison'!F9)),"N/A",'2_Growth_Comparison'!F7/'2_Growth_Comparison'!F9),"N/A")
A8: Adani Power — Sales / Employee (₹ lakh) | B8: =IFERROR(IF(OR(ISTEXT('2_Growth_Comparison'!B7),ISTEXT('2_Growth_Comparison'!B10)),"N/A",'2_Growth_Comparison'!B7*100/'2_Growth_Comparison'!B10),"N/A") | C8: =IFERROR(IF(OR(ISTEXT('2_Growth_Comparison'!C7),ISTEXT('2_Growth_Comparison'!C10)),"N/A",'2_Growth_Comparison'!C7*100/'2_Growth_Comparison'!C10),"N/A") | D8: =IFERROR(IF(OR(ISTEXT('2_Growth_Comparison'!D7),ISTEXT('2_Growth_Comparison'!D10)),"N/A",'2_Growth_Comparison'!D7*100/'2_Growth_Comparison'!D10),"N/A") | E8: =IFERROR(IF(OR(ISTEXT('2_Growth_Comparison'!E7),ISTEXT('2_Growth_Comparison'!E10)),"N/A",'2_Growth_Comparison'!E7*100/'2_Growth_Comparison'!E10),"N/A") | F8: =IFERROR(IF(OR(ISTEXT('2_Growth_Comparison'!F7),ISTEXT('2_Growth_Comparison'!F10)),"N/A",'2_Growth_Comparison'!F7*100/'2_Growth_Comparison'!F10),"N/A")
A10: Tata Power — Sales / Total Assets (x) | B10: =IFERROR(IF(OR(ISTEXT('2_Growth_Comparison'!B13),ISTEXT('2_Growth_Comparison'!B15)),"N/A",'2_Growth_Comparison'!B13/'2_Growth_Comparison'!B15),"N/A") | C10: =IFERROR(IF(OR(ISTEXT('2_Growth_Comparison'!C13),ISTEXT('2_Growth_Comparison'!C15)),"N/A",'2_Growth_Comparison'!C13/'2_Growth_Comparison'!C15),"N/A") | D10: =IFERROR(IF(OR(ISTEXT('2_Growth_Comparison'!D13),ISTEXT('2_Growth_Comparison'!D15)),"N/A",'2_Growth_Comparison'!D13/'2_Growth_Comparison'!D15),"N/A") | E10: =IFERROR(IF(OR(ISTEXT('2_Growth_Comparison'!E13),ISTEXT('2_Growth_Comparison'!E15)),"N/A",'2_Growth_Comparison'!E13/'2_Growth_Comparison'!E15),"N/A") | F10: =IFERROR(IF(OR(ISTEXT('2_Growth_Comparison'!F13),ISTEXT('2_Growth_Comparison'!F15)),"N/A",'2_Growth_Comparison'!F13/'2_Growth_Comparison'!F15),"N/A")
A11: Tata Power — Sales / Employee (₹ lakh) | B11: =IFERROR(IF(OR(ISTEXT('2_Growth_Comparison'!B13),ISTEXT('2_Growth_Comparison'!B16)),"N/A",'2_Growth_Comparison'!B13*100/'2_Growth_Comparison'!B16),"N/A") | C11: =IFERROR(IF(OR(ISTEXT('2_Growth_Comparison'!C13),ISTEXT('2_Growth_Comparison'!C16)),"N/A",'2_Growth_Comparison'!C13*100/'2_Growth_Comparison'!C16),"N/A") | D11: =IFERROR(IF(OR(ISTEXT('2_Growth_Comparison'!D13),ISTEXT('2_Growth_Comparison'!D16)),"N/A",'2_Growth_Comparison'!D13*100/'2_Growth_Comparison'!D16),"N/A") | E11: =IFERROR(IF(OR(ISTEXT('2_Growth_Comparison'!E13),ISTEXT('2_Growth_Comparison'!E16)),"N/A",'2_Growth_Comparison'!E13*100/'2_Growth_Comparison'!E16),"N/A") | F11: =IFERROR(IF(OR(ISTEXT('2_Growth_Comparison'!F13),ISTEXT('2_Growth_Comparison'!F16)),"N/A",'2_Growth_Comparison'!F13*100/'2_Growth_Comparison'!F16),"N/A")
A13: Torrent Power — Sales / Total Assets (x) | B13: =IFERROR(IF(OR(ISTEXT('2_Growth_Comparison'!B19),ISTEXT('2_Growth_Comparison'!B21)),"N/A",'2_Growth_Comparison'!B19/'2_Growth_Comparison'!B21),"N/A") | C13: =IFERROR(IF(OR(ISTEXT('2_Growth_Comparison'!C19),ISTEXT('2_Growth_Comparison'!C21)),"N/A",'2_Growth_Comparison'!C19/'2_Growth_Comparison'!C21),"N/A") | D13: =IFERROR(IF(OR(ISTEXT('2_Growth_Comparison'!D19),ISTEXT('2_Growth_Comparison'!D21)),"N/A",'2_Growth_Comparison'!D19/'2_Growth_Comparison'!D21),"N/A") | E13: =IFERROR(IF(OR(ISTEXT('2_Growth_Comparison'!E19),ISTEXT('2_Growth_Comparison'!E21)),"N/A",'2_Growth_Comparison'!E19/'2_Growth_Comparison'!E21),"N/A") | F13: =IFERROR(IF(OR(ISTEXT('2_Growth_Comparison'!F19),ISTEXT('2_Growth_Comparison'!F21)),"N/A",'2_Growth_Comparison'!F19/'2_Growth_Comparison'!F21),"N/A")
A14: Torrent Power — Sales / Employee (₹ lakh) | B14: =IFERROR(IF(OR(ISTEXT('2_Growth_Comparison'!B19),ISTEXT('2_Growth_Comparison'!B22)),"N/A",'2_Growth_Comparison'!B19*100/'2_Growth_Comparison'!B22),"N/A") | C14: =IFERROR(IF(OR(ISTEXT('2_Growth_Comparison'!C19),ISTEXT('2_Growth_Comparison'!C22)),"N/A",'2_Growth_Comparison'!C19*100/'2_Growth_Comparison'!C22),"N/A") | D14: =IFERROR(IF(OR(ISTEXT('2_Growth_Comparison'!D19),ISTEXT('2_Growth_Comparison'!D22)),"N/A",'2_Growth_Comparison'!D19*100/'2_Growth_Comparison'!D22),"N/A") | E14: =IFERROR(IF(OR(ISTEXT('2_Growth_Comparison'!E19),ISTEXT('2_Growth_Comparison'!E22)),"N/A",'2_Growth_Comparison'!E19*100/'2_Growth_Comparison'!E22),"N/A") | F14: =IFERROR(IF(OR(ISTEXT('2_Growth_Comparison'!F19),ISTEXT('2_Growth_Comparison'!F22)),"N/A",'2_Growth_Comparison'!F19*100/'2_Growth_Comparison'!F22),"N/A")
A16: Comments
A17: SALES PER RUPEE OF ASSET (all five years computed from verified Annual Report data): Adani Power improved from ~0.39x (FY22) to a peak of ~0.65x (FY24), then fell back to ~0.41x (FY26) as its asset base ballooned ahead of revenue from new acquisitions still ramping up. Tata Power is stable in a ~0.37-0.45x band — typical of a regulated, asset-heavy integrated utility. Torrent Power is consistently the MOST asset-efficient of the three (~0.58-0.87x, peaking FY23 when DNH&DD volumes hit a still-small asset base) — its regulated distribution business generates more revenue per rupee of assets than pure thermal generation does. SALES PER EMPLOYEE: comparable across time within Torrent (parent employs most staff) but NOT comparable across companies — Adani and Tata employee counts are standalone-parent only, while their revenue is consolidated (Tata's discoms/TPREL staff sit in subsidiaries). Use the Torrent series as the benchmark and treat Adani/Tata Sales-per-Employee as indicative only, noting the basis in any write-up.

Sheet 4_Acquisitions
A1: 4. Business Acquisitions (last ~5 years) & Impact
A2: Deal size, status, and available data on post-acquisition impact on sales/profit/cash from operations.
A5: Company | B5: Date | C5: Target / Deal | D5: Deal Size (₹ cr) | E5: Status | F5: Route | G5: Impact on Sales/Profit/CFO post-acquisition
A6: Adani Power | B6: Mar 2022 | C6: Essar Power MP → Mahan Energen Ltd (1,200 MW, MP) | D6: >4,250 | E6: Completed | F6: IBC/CIRP | G6: Lifted total operating capacity; management cites new-acquisition depreciation as a near-term drag on PBT, but capacity/EBITDA growth outweighs it. No standalone P&L attribution disclosed publicly.
A7: Adani Power | B7: Feb 2023 | C7: DB Power (1,200 MW, Chhattisgarh) | D7: 7,017 (deal signed) | E7: LAPSED — long-stop date expired unconsummated | F7: Negotiated M&A | G7: None — deal did not close.
A8: Adani Power | B8: Aug 2024 | C8: Lanco Amarkantak → Korba Power Ltd (600 MW, Chhattisgarh) | D8: 4,101 | E8: NCLT-approved, completed | F8: IBC/CIRP | G8: Contributed to capacity growth to 17,550 MW (Q1 FY26); no standalone P&L split disclosed.
A9: Adani Power | B9: Aug 2024 | C9: Coastal Energen → Moxie Power Generation Ltd (1,200 MW, Tamil Nadu) — 49% JV with DAIT | D9: ~3,335 (to creditors) | E9: NCLT-approved, completed | F9: IBC/CIRP (JV, Adani 49%) | G9: Adds south-India footprint; equity-accounted as JV, so full revenue not consolidated line-by-line.
A10: Adani Power | B10: Jul 2025 | C10: Vidarbha Industries Power Ltd (600 MW, Nagpur) | D10: Not disclosed | E10: Completed | F10: IBC/CIRP | G10: Took total operating capacity to 18,150 MW.
A11: Adani Power | B11: ~Mar 2026 | C11: Jaiprakash Power Ventures Ltd — 24% stake via resolution plan (thermal + hydro assets) | D11: ~14,535 | E11: NCLT approved | F11: IBC/CIRP (implementing entity) | G11: Too recent for post-acquisition P&L data; JP Power stock jumped ~29% in 2 days on the news.
A12: Adani Power | B12: Dec 2025 (bid) | C12: GVK Energy — Alaknanda hydro (330 MW, Uttarakhand) | D12: ~3,000-4,000 (bid range) | E12: Frontrunner reported; completion unconfirmed | F12: IBC/CIRP (bidding) | G12: Not yet completed as of research date — verify current status.
A13: Adani Power | B13: 2024 (bid) | C13: KSK Mahanadi Power (1,800 MW, Chhattisgarh) | D13: ~27,000 (bid) | E13: Completion status unconfirmed | F13: IBC/CIRP (bidding) | G13: Verify current status directly.
A14: Tata Power | B14: Mar 2021 | C14: NESCO → TP Northern Odisha Distribution Ltd (TPNODL) — 51% | D14: 191 | E14: Completed | F14: PPP discom privatization | G14: Part of a wave of 4 Odisha discom acquisitions (2020-21) that materially grew the T&D segment's customer base (12.6mn customers) and revenue.
A15: Tata Power | B15: 2020-21 | C15: TP Central/Western/Southern Odisha Distribution Ltds (TPCODL/TPWODL/TPSODL) — 51% each | D15: Not found | E15: Completed | F15: PPP discom privatization | G15: See above — combined Odisha discom impact drove T&D revenue growth through FY22-24.
A16: Tata Power | B16: 2023 | C16: Resurgent Power Ventures — NRSS XXXVI Transmission Ltd & South East UP Power Transmission Co Ltd (transmission SPVs) | D16: Not found | E16: Completed | F16: M&A (transmission assets) | G16: Expands regulated transmission asset base; no standalone P&L disclosed.
... A22: Torrent Power | B22: Jun 2026 (SPA Feb 2026) | C22: Nabha Power Ltd — 100% (2x700 MW coal, Punjab), from L&T Power Development | D22: ~3,632-3,661 | E22: Completed | F22: M&A | G22: Lifts total generation capacity from ~5 GW to ~6.4 GW; stock rose ~39% in Apr 2026 partly on this news (pre-completion announcement effect).
A24: Comments
A25: All three companies have grown primarily through IBC/CIRP-route or PPP-route acquisitions rather than open-market M&A, reflecting the sector's history of stressed/under-construction assets (Adani Power, Tata Power distribution) and government discom-privatization programmes (Tata Power's Odisha discoms, Torrent Power's DNH&DD). Adani Power has been the most acquisitive by deal count and value (five completed + two pending IBC deals since 2022, plus a 24% stake in Jaiprakash Power via a ~₹14,535 cr resolution plan), consistent with its capacity nearly doubling since FY22. None of the three companies publicly disclose acquisition-specific post-deal P&L/cash-flow attribution — this had to be inferred qualitatively from capacity growth and management commentary; a precise before/after contribution analysis would require the acquired entities' standalone financial statements (available via MCA/ROC filings) cross-referenced against the parent's segment note.

Sheet 5_Shareholding_Pattern
A1: 5. Shareholding Pattern
A2: As at 31-Mar-2026 for Adani Power/Tata Power/Torrent Power — VERIFIED from each company's FY25-26 Annual Report. Major shareholder = >5% of equity.
A5: Metric | B5: Adani Power | C5: Tata Power | D5: Torrent Power | E5: Notes
A6: Promoter holding (%) | B6: 74.96% (Promoter & Promoter Group, per FY26 Annual Report shareholding table) | C6: 46.86% total promoter group; Tata Sons Pvt Ltd alone = 45.21% (per FY26 Annual Report) | D6: 51.09% — Torrent Investments Ltd (formerly Torrent Investments Pvt Ltd), unchanged FY25→FY26 (per FY26 Annual Report) | E6: VERIFIED from FY25-26 Annual Reports (uploaded).
A7: Promoter pledge | B7: No pledge of promoter shares disclosed in the FY26 Annual Report (only routine subsidiary-loan security pledges by the Company, unrelated to promoter shareholding). | C7: 'Company has not raised loans during the year on the pledge of securities held in its subsidiaries, joint ventures...' — no promoter share pledge disclosed. | D7: No pledge of promoter shares disclosed in the FY26 Annual Report. | E7: VERIFIED (nil promoter pledge) from FY25-26 Annual Reports for all three.
A8: FII / FPI holding (%) | B8: 11.74% (secondary-source snapshot; not separately re-verified in the Annual Report text extract) | C8: ~10.0-10.04% (secondary-source snapshot) | D8: 8.4%-14.2% (conflicting across sources/dates) | E8: Category-wise FII/DII % not captured from the Annual Report's shareholding table in this pass — cross-check the full SHP table in each PDF if needed.
A9: DII / Mutual Fund holding (%) | B9: 3.69% (DII, secondary-source snapshot) | C9: 8.64% (DII, one source) vs 18.28% (DII, another) — MFs alone ~8.89-9.63% | D9: SBI Mutual Fund confirmed at 8.57% (FY26, up from 7.95% FY25) — VERIFIED from Annual Report top-10-shareholders table. | E9: 6-month change for SBI MF in Torrent Power (7.95%→8.57%) is now VERIFIED; other DII figures remain secondary-source.
A10: Public / Retail (%) | B10: 9.62% (secondary-source snapshot) | C10: ~21.5-25.6% (free float, incl. FII+DII+public) | D10: ~9.3-17.68% (conflicting by source/date)
A11: Free float (100% - promoter%) | B11: ~25.04% | C11: ~53.14% | D11: ~48.91% | E11: Approx.; = 100% - promoter%.
A12: Named shareholder(s) holding >5% | B12: NONE currently >5% besides promoter group — GQG Partners (Goldman Sachs Trust II - Goldman Sachs GQG Partner) now holds only 3.30% as of FY26 (down from ~7.7-8.1% in 2023), per the FY26 Annual Report's top-10-shareholders table. No other non-promoter holder exceeds 5%. | C12: Life Insurance Corporation of India (LIC) — 5.18% as at 31-Mar-2026 (up from 2.96% at 31-Mar-2025), crossing the 5% threshold during FY26 — VERIFIED from the FY26 Annual Report's 'shareholders holding more than 5%' table. | D12: Gujarat Urja Vikas Nigam Ltd (GUVNL, Gujarat's state power utility) — 6.95%, unchanged FY25→FY26 — VERIFIED from the FY26 Annual Report's top-10-shareholders table. (Earlier flagged 'Aditya Birla Group ~6.34%' claim was NOT found in the primary source and should be disregarded.) | E12: All three figures in this row are now VERIFIED from primary Annual Reports, replacing prior unconfirmed secondary-source claims.
A14: Comments
A15: Adani Power has by far the highest promoter concentration (~75%) of the three, leaving the smallest free float (~25%) — typical of Adani Group listed entities, and a legacy of tightened promoter control after the 2023 Hindenburg-report episode (with an emphasis on 'zero pledge' messaging across group companies since). Tata Power's promoter stake (Tata Sons, ~47%) is the lowest of the three, giving it the widest institutional/public float and closest to the SEBI minimum public shareholding norms. Torrent Power sits in between (~51% promoter). Shareholding figures pulled from secondary aggregators showed real inconsistencies across sources/dates for FII/DII splits at all three companies — before using these in the final submission, pull ONE consistent-quarter shareholding-pattern XBRL filing per company directly from BSE/NSE (each company files this quarterly) rather than mixing snapshots from different dates.

Sheet 6_Business_Segments
A1: 6. Reportable Business Segments (Ind AS 108) — VERIFIED from Annual Reports
A2: ₹ crore, consolidated, FY22-FY26. Extracted directly from the 'Segment Reporting' notes of each company's audited Annual Reports.
A5: ADANI POWER — 2 segments: 'Power Generation & related activities' + 'Trading, Investment & other activities'
A6: Particulars | B6: FY22 | C6: FY23 | D6: FY24 | E6: FY25 | F6: FY26
A7: Segment Revenue — Power Generation | B7: 27221.78 | C7: 37895.85 | D7: 50014.16 | E7: 56107.06 | F7: 54240.52
A8: Segment Revenue — Trading/Investment/Other | B8: 489.4 | C8: 877.45 | D8: 337.09 | E8: 96.03 | F8: 0
A9: Segment Results — Power Generation | B9: 6571.37 | C9: 6957.13 | D9: 20557.22 | E9: 16540.39 | F9: 15757.55
A10: Segment Results — Trading/Investment/Other | B10: 5.76 | C10: 717.57 | D10: 234.29 | E10: -1.81 | F10: 13.68
A11: Segment Assets — Power Generation | B11: 81888.09 | C11: 84364.22 | D11: 91378.85 | E11: 111162.48 | F11: 139777.31
A12: Segment Assets — Trading/Investment/Other | B12: 42.02 | C12: 1134.26 | D12: 203.86 | E12: 1328.18 | F12: 1354.52
A13: FY22-23 results are as restated in the FY23 report after a CODM methodology change. FY26 Trading revenue was nil; segment results shown are pre-tax basis per each year's note.
A15: TATA POWER — 4 segments: Generation (Thermal & Hydro), Renewables, Transmission & Distribution, Others
A16: Particulars | B16: FY22 | C16: FY23 | D16: FY24 | E16: FY25 | F16: FY26
A17: Segment Revenue — Generation/Thermal & Hydro | B17: 11211.03 | C17: 18211.35 | D17: 19613.61 | E17: 19739.07 | F17: 11635.93
A18: Segment Revenue — Renewables | B18: 7748.9 | C18: 8196.91 | D18: 10175.29 | E18: 9876.36 | F18: 15027.82
A19: Segment Revenue — Transmission & Distribution | B19: 27493.17 | C19: 34529.36 | D19: 36205.82 | E19: 39120.52 | F19: 41338.59
A20: Segment Revenue — Others | B20: 317.8 | C20: 413.56 | D20: 430.62 | E20: 431.04 | F20: 431.79
A21: Segment Results — Generation/Thermal & Hydro | B21: 2632.75 | C21: 5092.16 | D21: 2569.61 | E21: 2878.91 | F21: 1137.94
A22: Segment Results — Renewables | B22: 1923.57 | C22: 1932.01 | D22: 2147.1 | E22: 2880.68 | F22: 4340.93
A23: Segment Results — Transmission & Distribution | B23: 2138.49 | C23: 2197.68 | D23: 2418.22 | E23: 3128.27 | F23: 4307.95
A24: Segment Results — Others | B24: -286.03 | C24: -308.17 | D24: 105.38 | E24: 112.8 | F24: 104.72
A25: Segment Assets — Generation/Thermal & Hydro | B25: 38201.93 | C25: 41201.04 | D25: 39315.88 | E25: 39708.11 | F25: 41697.31
A26: Segment Assets — Renewables | B26: 27589.28 | C26: 29744.49 | D26: 40459.25 | E26: 51355.61 | F26: 56921.28
A27: Segment Assets — Transmission & Distribution | B27: 32411.34 | C27: 37477.26 | D27: 42059.9 | E27: 45707.75 | F27: 53428.87
A28: Segment Assets — Others + Unallocable | B28: 14682.04 | C28: 19926.25 | D28: 17718.46 | E28: 19939.82 | F28: 23124.32
A29: Revenue shown gross (before inter-segment eliminations of ~₹4,000-5,400cr/yr, mostly Generation→T&D coal/power sales). 'Generation' was renamed 'Thermal & Hydro' from the FY25 report. FY23 Generation result of ₹5,092cr was later restated in the FY24 report to ₹1,528cr segment result + ₹3,564cr exceptional; the as-originally-reported figure is shown here. FY26 Thermal & Hydro result derived as total-minus-other-segments (₹9,891.54cr total). FY26 revenue drop in Thermal & Hydro reflects the Mundra shutdown; Renewables surged on new capacity.
A31: TORRENT POWER — NO reportable segments under Ind AS 108
A32: Per Note 53/54 ('Operating Segments') of Torrent Power's FY23 Annual Report (and equivalent notes in other years): "the Group does not have any reportable segment as per Ind AS-108 'Operating Segments'" — the CODM manages Generation, Transmission and Distribution as ONE integrated electricity business, and the cable business is immaterial (below reportable thresholds for revenue, profit and assets). This is an important verified correction: earlier drafts of this sheet assumed 3 reportable segments (Generation/Transmission/Distribution) from the MD&A's business description — the MD&A discusses those businesses operationally, but the statutory segment note reports a single segment. Any segment-level financial comparison for Torrent must therefore rely on MD&A operating metrics (e.g., FY23 distribution electricity purchases +63.2% YoY to 30,037 MU after the DNH&DD takeover), not audited segment P&L data, because none is published.
A38: Comparative analysis — who is doing well in which segment?
A39: GENERATION is the only segment where all three effectively compete, and the verified numbers show a stark contrast: Adani Power's generation segment grew revenue ~2.0x (₹27,222cr FY22 → ₹54,241cr FY26) with segment results of ₹15,758-20,557cr in FY24-26 — vastly more profitable than Tata Power's generation segment (results of only ₹1,138-2,879cr on ₹11,636-19,739cr revenue in the same years, dragged by the Mundra plant's fuel economics and eventual shutdown). Adani is unambiguously the generation winner. RENEWABLES: only Tata Power reports it separately, and it is now their growth engine — revenue up ~1.9x (₹7,749cr FY22 → ₹15,028cr FY26), results up 2.3x (₹1,924cr → ₹4,341cr), and segment assets up 2.1x to ₹56,921cr, overtaking every other Tata segment. Adani Power has no renewables segment (that sits in sister company Adani Green). TRANSMISSION & DISTRIBUTION: Tata Power's largest and steadiest segment — revenue grew ₹27,493cr → ₹41,339cr (FY22→FY26, boosted by the Odisha discoms) with consistently positive, regulated-return results (₹2,138cr → ₹4,308cr). Torrent's distribution business is economically similar (regulated, stable) but not separately reported. INDUSTRY CONTEXT: India's power demand grew ~7-8%/yr (CEA) over this period — Adani's generation growth (~13% CAGR) and Tata's renewables growth (~21% CAGR) both outpaced the sector, largely through acquisitions and capacity build-out respectively, while Tata's generation segment underperformed the sector.

Sheet 6b_Segment_Chart_Data
A1: Year | B1: Tata Generation Rev | C1: Tata Renewables Rev | D1: Tata T&D Rev | E1: Adani Generation Rev
A2: FY22 | B2: 11211.03 | C2: 7748.9 | D2: 27493.17 | E2: 27221.78
A3: FY23 | B3: 18211.35 | C3: 8196.91 | D3: 34529.36 | E3: 37895.85
A4: FY24 | B4: 19613.61 | C4: 10175.29 | D4: 36205.82 | E4: 50014.16
A5: FY25 | B5: 19739.07 | C5: 9876.36 | D5: 39120.52 | E5: 56107.06
A6: FY26 | B6: 11635.93 | C6: 15027.82 | D6: 41338.59 | E6: 54240.52

Sheet 7_Group_Structure
A1: 7. Group Structure — Subsidiaries
A2: Key subsidiaries and % holding, with one-line business description.
A5: Company | B5: Subsidiary | C5: % Holding | D5: Business Description
A6: Adani Power | B6: Mahan Energen Ltd (MEL) | C6: 94% (per FY26 AOC-1 — earlier reported as 100%) | D6: 1,200+ MW coal thermal, MP; ex-Essar Power MP (CIRP, Mar 2022). FY26: turnover ₹3,614cr, PAT ₹784cr.
A7: Adani Power | B7: Korba Power Ltd (KPL, ex-Lanco Amarkantak) | C7: 100% | D7: 600 MW coal thermal, Chhattisgarh (CIRP, Sep 2024). FY26: turnover ₹1,552cr, PAT ₹354cr.
A8: Adani Power | B8: Moxie Power Generation Ltd (ex-Coastal Energen) | C8: 49% — but consolidated as a SUBSIDIARY in AOC-1 Part A (control basis), not a JV | D8: 1,200 MW, Thoothukudi, Tamil Nadu. FY26: turnover ₹2,985cr, PAT ₹268cr. Listed in AOC-1 subsidiaries despite 49% equity — control established via arrangement with DAIT.
A9: Adani Power | B9: Vidarbha Industries Power Ltd (VIPL) | C9: 100% (acquired 07-Jul-2025) | D9: 600 MW, Nagpur (CIRP). FY26: turnover ₹1,327cr, PAT ₹347cr.
A10: Adani Power | B10: Adani Power Dahej Ltd / Pench Thermal Energy (MP) Ltd / Kutchh Power Generation Ltd | C10: 100% each | D10: Greenfield thermal project SPVs (Dahej, Pench, Kutchh).
A11: Adani Power | B11: Anuppur Thermal Energy (MP) / Mirzapur Thermal Energy (UP) / Orrisa Thermal Energy | C11: 100% each (acquired/renamed 2024) | D11: New thermal project SPVs for capacity expansion (Anuppur, Mirzapur, Odisha sites).
A12: Adani Power | B12: Mahan Fuel Management / Resurgent Fuel Management Ltd | C12: 100% each | D12: Fuel sourcing/management SPVs.
A13: Adani Power | B13: Alcedo / Chandenvalle / Emberiza Infra Park Ltd | C13: 100% each | D13: Infrastructure park SPVs.
A14: Adani Power | B14: Adani Atomic Energy Ltd (AAEL) | C14: 100% (incorporated 11-Feb-2026) | D14: Nuclear power entry post SHANTI Act 2025.
A15: Adani Power | B15: Adani Power Middle East Ltd (AED) / Adani Power Global Pte Ltd (US$) | C15: 100% each (incorporated 2024) | D15: Overseas ventures (Middle East; Singapore trading/holding).
A16: Adani Power | B16: Adani Power Resources Ltd | C16: 51% | D16: Resource-related SPV (immaterial size).
... A30: Torrent Power | B30: [TOTAL: ~60 entities in FY26 AOC-1 — 53 at 100%, 5 at 74%, 1 at 95%, 1 at 51%] | C30: — | D30: Verified from the FY26 Annual Report AOC-1 statement.

Sheet 8_Associates_JVs
A1: 8. Associates & Joint Ventures
A5: Company | B5: Associate / JV | C5: Stake | D5: Notes
A6: Adani Power | B6: Wangchhu Hydroelectric Power Ltd (Bhutan) | C6: JV (per FY26 AOC-1 Part B — the Group's only listed associate/JV) | D6: 570 MW Wangchhu hydro project JV with Druk Green Power Corp (~₹6,000 cr); Shareholders Agreement Sep 2025; 'yet to commence operations' per AOC-1. VERIFIED.
A7: Adani Power | B7: Moxie Power Generation Ltd — RECLASSIFIED | C7: 49% equity but consolidated as SUBSIDIARY (see Sheet 7) | D7: CORRECTION: earlier flagged as a JV; the FY26 AOC-1 lists it under Part A (Subsidiaries) — Adani has control despite 49% equity.
A8: Adani Power | B8: Jaiprakash Power Ventures Ltd (JPVL) | C8: 24% (indirect, via resolution plan) | D8: Adani Power as 'Implementing Entity'; NCLT-approved ~Mar 2026 (~₹14,535 cr). Not yet in FY26 AOC-1 Part B (transaction completing post year-end).
A9: Tata Power | B9: Tata Projects, Resurgent Power Ventures (26%), industrial JVs & associates | C9: Various | D9: Tata Power holds numerous associates/JVs (share of profit ₹708cr FY26, ₹793cr FY25 per consolidated P&L); full Part B list in FY26 Annual Report AOC-1.
A10: Tata Power | B10: Dorjilung Hydro Power Ltd (Bhutan) | C10: Stake not disclosed in extract | D10: 1,125 MW hydro project under development with Druk Green.
A11: Torrent Power | B11: Associates (2 per earlier AOC-1 references) | C11: Not extracted | D11: Torrent's FY26 AOC-1 Part B not extracted in this pass — the Part A subsidiary data above is verified; pull Part B from the same annexure if associate detail is needed.

Sheet 9_Investments
A1: 9. Investments (excl. Subsidiaries/Associates/JVs) — up to FY2023
A5: Company | B5: Finding | C5: Data Quality
A6: Adani Power | B6: VERIFIED from FY23 consolidated Investments notes: NON-CURRENT — ₹42.51cr total as at 31-Mar-2023 (vs ₹0.01cr FY22), comprising ₹42.50cr of 0.001% Optionally Convertible Cumulative Debentures of Sal Technologies and Solutions Ltd (4.25cr units, new in FY23), a ₹0.01cr National Saving Certificate, and a negligible FVTOCI equity stake in Adani Naval Defence Systems & Technologies Ltd. CURRENT — ₹611.54cr in unquoted mutual funds (SBI Liquid Fund ₹608.42cr + SBI Overnight Fund ₹3.12cr) vs ₹183.24cr (FY22, SBI Overnight only). Pattern: treasury parked in liquid MFs, scale rising with cash generation; almost no discretionary long-term securities portfolio. | C6: VERIFIED (FY23 Annual Report)
A7: Tata Power | B7: VERIFIED from FY23 consolidated Investments note: non-current investments OTHER than associates/JVs totalled ₹1,301.21cr as at 31-Mar-2023 (vs ₹1,169.81cr FY22), comprising equity shares carried at FVTOCI/FVTPL and Government Securities (unquoted) of ₹128.10cr (FY22: ₹124.26cr). The earlier secondary-source figure of '~₹12,064cr non-current investments' conflated investments in associates/JVs (equity-method carrying values) with this third-party portfolio — use ₹1,301cr for the ex-subsidiary/associate/JV basis the assignment asks for. | C7: VERIFIED (FY23 Annual Report) — replaces earlier unverified figure
A8: Torrent Power | B8: VERIFIED from Note 10 (Other Investments) and Note 16 (Current Investments) of the CONSOLIDATED Financial Statements, FY23 Annual Report ('Notes forming part of the consolidated financial statements for the year ended March 31, 2023'): NON-CURRENT — ₹15.94cr as at 31-Mar-2023 (down from ₹132.82cr FY22), comprising Government of India bonds ₹15.89cr (the GERC Multi-Year-Tariff-mandated 'contingency reserve' for its Gujarat distribution licences) + ₹0.05cr equity in UNM Foundation. CURRENT — ₹787.75cr total (vs ₹273.70cr FY22): unquoted mutual funds ₹785.82cr + statutory contingency-reserve investments ₹1.93cr. CORRECTION: an earlier pass of this sheet had pulled the STANDALONE (parent-only) figures for current investments (₹682.31cr) by mistake — the consolidated figure is ₹787.75cr, ~₹105cr higher because subsidiaries hold additional mutual fund investments. Non-current figure is unchanged (identical at both levels). The GoI-bond holdings are regulatory-mandated (usable only for GERC-specified purposes), not discretionary treasury. | C8: VERIFIED CONSOLIDATED (FY23 Annual Report) — corrected from standalone
A10: All three companies' figures above are now extracted directly from the consolidated 'Investments' notes of the FY2022-23 Annual Reports uploaded to the repo. Common pattern: all three park treasury cash in liquid/overnight mutual funds; Torrent additionally holds regulatory-mandated GoI bonds (GERC contingency reserve); none runs a material discretionary securities portfolio.

Sheet 10_Financing_Changes
A1: 10. Major Changes in Financing (last 5 years)
A5: Company | B5: Date | C5: Event | D5: Amount (₹ cr)
A6: Adani Power | B6: Jan 2024 | C6: CRISIL upgraded bank-facility rating to AA-/Stable from A/Stable | D6: —
A7: Adani Power | B7: Feb 2025 | C7: CRISIL upgraded to AA/Stable from AA-/Positive on ₹38,000 cr long-term bank facilities; assigned AA/Stable to proposed NCDs | D7: 38,000 (facilities); 11,000 (proposed NCDs)
A8: Adani Power | B8: FY22→FY24 | C8: Deleveraging: net debt/EBITDA fell from ~4.0x (Mar-22) to 3.3x (Mar-23) to 1.4x (Mar-24) | D8: Net debt ~26,270-26,545 (Q4 FY24)
A9: Adani Power | B9: FY24→FY25 | C9: Shareholders' funds grew from ₹43,145 cr (31-Mar-24) to ₹56,347 cr (31-Mar-25) | D9: +13,202
A10: Adani Power | B10: 1-Aug-2025 / 22-Sep-2025 | C10: 1:5 stock split announced / effective (face value ₹10 → ₹2) — capital structure change, not a capital raise | D10: —
A11: Tata Power | B11: 30-Jul-2020 | C11: ₹2,600 cr preferential allotment of ~49.06 cr shares to promoter Tata Sons at ₹53/share, to cut debt & fund capex; raised promoter stake 35.27%→45.21% | D11: 2,600
A12: Tata Power | B12: Apr-2024 | C12: CRISIL upgraded to AA+/Stable from AA/Positive, citing improved generation/distribution profitability | D12: —
A13: Tata Power | B13: FY22→FY24 | C13: Deleveraging: net debt/EBITDA fell from ~4.5x (FY22) to 3.8x (FY23), sustained <4.0x through FY24; debtor days improved from >150 to ~102 days | D13: —
A14: Torrent Power | B14: Dec-2024 | C14: Maiden QIP — ₹3,500 cr raised at ₹1,503/share (~2.32 cr shares); first Torrent Group equity raise in ~3 decades; ~4x oversubscribed (bids ~₹14,000 cr) | D14: 3,500
A15: Torrent Power | B15: Apr-2022 | C15: Series 8 NCDs — ₹600 cr (coupons 6.20%-7.45% across tenors) | D15: 600
A16: Torrent Power | B16: Mar-2026 | C16: NCD issuance, 8/9/10-yr tenor | D16: 2,000
... A18: Torrent Power | B18: Dec-2023 / Feb-2024 / Feb-2025 | C18: CRISIL reaffirmed AA+/Stable (LT) and A1+ (ST) at each review; net debt/EBITDA improved 2.20x (FY24) → 1.40x (FY25) | D18: —
A20: Comments
A21: All three companies have been actively de-leveraging and improving credit ratings over the last five years — a sector-wide trend as thermal-generation cash flows normalized post-COVID and renewable capex was increasingly funded with cheaper, longer-tenor debt. Adani Power's improvement is the most dramatic in relative terms (net debt/EBITDA from ~4x to ~1.4x within two years), consistent with its swing from losses to strong profitability. Tata Power funded its 2020 deleveraging via a promoter-only preferential allotment rather than a public offering, keeping the raise off the open market. Torrent Power is notable for having gone ~30 years without a public equity raise before its Dec-2024 QIP — a signal of a more conservative, debt/promoter-funded capital structure historically, now shifting toward institutional equity to fund its large (₹80,000 cr) five-year capex programme.

Sheet 11_Returns_Volatility
A1: 11. Share Price Return vs Sector Index (weekly, 14-Jul-2025 to 15-Jul-2026) & Volatility
A2: COMPUTED from actual Yahoo Finance weekly adjusted-close data (split-adjusted), saved to repo as *_weekly.htm and parsed. 54 weekly points per series. Nifty Energy = sector index. Nifty 50 column pending (see note).
A5: Metric | B5: Adani Power | C5: Tata Power | D5: Torrent Power | E5: Nifty Energy (sector) | F5: Nifty 50 (market)
A6: Price at start (14-Jul-2025, adj) | B6: 118.93 | C6: 405.39 | D6: 1,349.89 | E6: 36,231.65 | F6: 24,968.40
A7: Price at end (15-Jul-2026) | B7: 218.97 | C7: 380.90 | D7: 1,441.10 | E7: 39,381.25 | F7: 24,078.50
A8: 52-week weekly-close range | B8: 113.40 - 243.37 | C8: 343.12 - 441.81 | D8: 1,204.41 - 1,730.01 | E8: 33,098.30 - 40,878.00 | F8: 22,713.10 - 26,328.55
A9: 1-year return (COMPUTED) | B9: +84.1% | C9: -6.0% | D9: +6.8% | E9: +8.7% | F9: -3.6%
A10: Weekly return std dev (COMPUTED) | B10: 4.95% | C10: 2.90% | D10: 4.55% | E10: 2.30% | F10: 1.70%
A11: Annualized volatility = sd x sqrt(52) | B11: 35.7% | C11: 20.9% | D11: 32.8% | E11: 16.6% | F11: 12.3%
A12: Beta vs Nifty 50 / market (COMPUTED) | B12: 1.13 | C12: 0.62 | D12: 1.46 | E12: 0.03 | F12: 1.00
A13: Beta vs Nifty Energy / sector (COMPUTED) | B13: 0.54 | C13: 0.03 | D13: 0.30 | E13: 1.00 | F13: n/a
A14: Return vs market (stock - Nifty 50) | B14: +87.7 pts | C14: -2.5 pts | D14: +10.3 pts | E14: +12.3 pts | F14: —
A15: Return vs sector (stock - Nifty Energy) | B15: +75.4 pts | C15: -14.7 pts | D15: -1.9 pts | E15: — | F15: —
A17: Data note
A18: COMPLETE: all five series (3 stocks + Nifty 50 + Nifty Energy) parsed from the Yahoo Finance Historical Data pages saved in the repo (54 weekly adjusted-close points each, 14-Jul-2025 to 15-Jul-2026, split-adjusted). Weekly returns, standard deviations, annualized volatility, and betas computed from this data - see the Weekly_Price_Data sheet for the full series and the rebased performance chart below.
A22: Comments — which share is most volatile?
A23: ANSWER (computed from 54 weekly observations, split-adjusted): ADANI POWER is the most volatile of the three — weekly-return standard deviation 4.95% (annualized ~36%), vs Torrent Power 4.55% (~33%) and Tata Power 2.90% (~21%). The sector index (Nifty Energy) sat at 2.30% weekly (~17% annualized) — all three stocks were roughly 1.3-2.2x as volatile as their sector index. RETURNS: Adani Power massively outperformed (+84% vs the sector's +9%), Torrent Power roughly tracked the sector (+6.8%), and Tata Power underperformed (-6.0%). Note the LOW computed betas vs Nifty Energy (0.03-0.54): Nifty Energy is dominated by Reliance/ONGC (oil & gas), so these power stocks move on company-specific news far more than on the 'sector' index — high volatility with low index correlation. Interpret beta accordingly. VS THE MARKET: Nifty 50 fell -3.6% over the window, so all three power stocks outperformed the broad market (Adani by ~88 points); market betas vs Nifty 50 are 1.13 (Adani), 0.62 (Tata) and 1.46 (Torrent).

Sheet Weekly_Price_Data
A1: Week Ending | B1: Adani Power (adj ₹) | C1: Tata Power (₹) | D1: Torrent Power (₹) | E1: Nifty Energy | F1: Nifty 50 | G1: Adani wk ret | H1: Tata wk ret | I1: Torrent wk ret | J1: NiftyEnergy wk ret | K1: Adani (base=100) | L1: Tata (base=100) | M1: Torrent (base=100) | N1: NiftyEnergy (base=100)
A2: 2025-07-14 | B2: 118.93 | C2: 405.39 | D2: 1349.89 | E2: 36231.65 | F2: 24968.4 | K2: 100 | L2: 100 | M2: 100 | N2: 100
A3: 2025-07-21 | B3: 114 | C3: 392.92 | D3: 1307.38 | E3: 35250.5 | F3: 24837 | G3: -0.041453 | H3: -0.030761 | I3: -0.031491 | J3: -0.02708 | K3: 95.85 | L3: 96.92 | M3: 96.85 | N3: 97.29
A4: 2025-07-28 | B4: 113.4 | C4: 386.9 | D4: 1270.59 | E4: 34889 | F4: 24565.35 | G4: -0.005263 | H4: -0.015321 | I4: -0.02814 | J4: -0.010255 | K4: 95.35 | L4: 95.44 | M4: 94.13 | N4: 96.29
A5: 2025-08-04 | B5: 115.38 | C5: 376.47 | D5: 1317.54 | E5: 34391.95 | F5: 24363.3 | G5: 0.01746 | H5: -0.026958 | I5: 0.036951 | J5: -0.014247 | K5: 97.02 | L5: 92.87 | M5: 97.6 | N5: 94.92
A6: 2025-08-11 | B6: 116.81 | C6: 382.93 | D6: 1311.42 | E6: 34469.05 | F6: 24631.3 | G6: 0.012394 | H6: 0.017159 | I6: -0.004645 | J6: 0.002242 | K6: 98.22 | L6: 94.46 | M6: 97.15 | N6: 95.14
A7: 2025-08-18 | B7: 118.86 | C7: 383.23 | D7: 1264.47 | E7: 34507.6 | F7: 24870.1 | G7: 0.01755 | H7: 0.000783 | I7: -0.035801 | J7: 0.001118 | K7: 99.94 | L7: 94.53 | M7: 93.67 | N7: 95.24
A8: 2025-08-25 | B8: 120.13 | C8: 371.85 | D8: 1210.52 | E8: 33638.65 | F8: 24426.85 | G8: 0.010685 | H8: -0.029695 | I8: -0.042666 | J8: -0.025181 | K8: 101.01 | L8: 91.73 | M8: 89.68 | N8: 92.84
A9: 2025-09-01 | B9: 121.94 | C9: 383.42 | D9: 1245.63 | E9: 34297.9 | F9: 24741 | G9: 0.015067 | H9: 0.031115 | I9: 0.029004 | J9: 0.019598 | K9: 102.53 | L9: 94.58 | M9: 92.28 | N9: 94.66
A10: 2025-09-08 | B10: 129.71 | C10: 383.87 | D10: 1250.47 | E10: 34940.3 | F10: 25114 | G10: 0.06372 | H10: 0.001174 | I10: 0.003886 | J10: 0.01873 | K10: 109.06 | L10: 94.69 | M10: 92.63 | N10: 96.44
A11: 2025-09-15 | B11: 141.88 | C11: 393.86 | D11: 1247.21 | E11: 35745.75 | F11: 25327.05 | G11: 0.093825 | H11: 0.026024 | I11: -0.002607 | J11: 0.023052 | K11: 119.3 | L11: 97.16 | M11: 92.39 | N11: 98.66
A12: 2025-09-22 | B12: 146.25 | C12: 381.44 | D12: 1216.44 | E12: 34830 | F12: 24654.7 | G12: 0.030801 | H12: -0.031534 | I12: -0.024671 | J12: -0.025618 | K12: 122.97 | L12: 94.09 | M12: 90.11 | N12: 96.13
A13: 2025-09-29 | B13: 147.38 | C13: 392.47 | D13: 1204.41 | E13: 35375.9 | F13: 24894.25 | G13: 0.007726 | H13: 0.028917 | I13: -0.00989 | J13: 0.015673 | K13: 123.92 | L13: 96.81 | M13: 89.22 | N13: 97.64
A14: 2025-10-06 | B14: 149.7 | C14: 387.7 | D14: 1222.36 | E14: 35393.95 | F14: 25285.35 | G14: 0.015742 | H14: -0.012154 | I14: 0.014904 | J14: 0.00051 | K14: 125.87 | L14: 95.64 | M14: 90.55 | N14: 97.69
... A53: 2026-07-06 | B53: 218.45 | C53: 381.3 | D53: 1419.4 | E53: 39242.05 | F53: 24206.9 | G53: -0.015059 | H53: 0.016258 | I53: 0.038712 | J53: 0.00162 | K53: 183.68 | L53: 94.06 | M53: 105.15 | N53: 108.31
A54: 2026-07-13 | B54: 226.17 | C54: 377.7 | D54: 1465.3 | F54: 24052.05 | G54: 0.03534 | H54: -0.009441 | I54: 0.032338 | K54: 190.17 | L54: 93.17 | M54: 108.55
A55: 2026-07-15 | B55: 218.97 | C55: 380.9 | D55: 1441.1 | E55: 39381.25 | F55: 24078.5 | G55: -0.031834 | H55: 0.008472 | I55: -0.016515 | J55: 0.003547 | K55: 184.12 | L55: 93.96 | M55: 106.76 | N55: 108.69

Sheet 12_Major_Announcements
A1: 12. Major Announcements — Adani Power (last ~12 months) & Price Reaction
A2: Target company only, per assignment. Dates approximate (secondary-source aggregated) — cross-check exact filing dates on BSE corporate announcements page before final submission.
A5: Date (approx.) | B5: Announcement | C5: Reported Price Reaction | D5: Nearest known price (₹)
A6: 07-Jul-2025 | B6: Completed acquisition of Vidarbha Industries Power Ltd (600 MW) — total capacity to 18,150 MW | C6: Not quantified in sources found
A7: 01-Aug-2025 | B7: Q1 FY26 results: PAT ₹3,305 cr (down 15.5% YoY); 1:5 stock split announced | C7: Not quantified
A8: Sep-2025 | B8: Adani Power–Druk Green (Bhutan) Shareholders Agreement — 570 MW Wangchhu hydro (~₹6,000 cr) | C8: Not quantified
A9: 22-Sep-2025 | B9: 1:5 stock split effective (face value ₹10→₹2) | C9: Mechanical price adjustment (~1/5th), not a market reaction
A10: 30-Oct-2025 | B10: Q2 FY26 results: PAT ~₹2,906-2,953 cr (down ~11-12% YoY); secured 4.5 GW new long-term PPAs | C10: Not quantified
A11: 14-Nov-2025 | B11: Letter of Award — 3,200 MW Assam UMPP (~₹48,000 cr investment, DBFOO) | C11: 'Share price surge reported' (source did not quantify %)
A12: Nov-2025 | B12: 24% stake in Jaiprakash Power Ventures via ₹14,535 cr resolution plan — creditors approved (89% votes) | C12: JP Power (the target) stock jumped ~29% in two days — Adani Power's own reaction not quantified in sources found
A13: 05-Jan-2026 | B13: News coverage: stock up ~40% over trailing 12 months | C13: +40% (12-mo, as reported that day) | D13: 146.20
A14: 11-Feb-2026 | B14: Incorporation of Adani Atomic Energy Ltd — entry into nuclear power | C14: Not quantified
A15: ~Mar-2026 | B15: NCLT approval of Jaiprakash Power Ventures resolution plan | C15: Not quantified
A16: 29-Apr-2026 | B16: Q4/FY26 results: Q4 PAT ₹4,271 cr (+64% YoY); FY26 PAT ₹12,971 cr vs ₹12,750 cr FY25 | C16: Not quantified
A17: 05-May-2026 | B17: Stock hits 52-week high, intraday | C17: Record high reached | D17: 234.35
A18: 22-May-2026 | B18: Profit-booking reported post ~100% 1-year return | C18: ~6% off high; ~100% 1-yr return cited that day | D18: ~220.00
A19: 13-Jul-2026 | B19: Filing on encumbrance/non-disposal undertaking re: Jaiprakash Power shares (in role as JPVL implementing entity) | C19: Not quantified
A21: Note on this section
A22: Most individual-announcement price reactions (in %) were NOT disclosed in the secondary news sources found via search — only a few data points (the 40% 12-month move reported 5-Jan-2026, the 52-week high of ₹234.35 on 5-May-2026, and the ~100% 1-yr return cited 22-May-2026) could be tied to a specific date and price. For a proper event-study chart (price in a window around each announcement date), pull the daily closing price for the 5 days before/after each announcement from NSE historical data and compute the % reaction — the chart below plots the sparse real data points we do have as a starting frame; extend it once you have the daily series.

Sheet 12b_Announcement_Chart_Data
A1: Week Ending | B1: Adani Power (adj ₹) | C1: Event that week
A2: 2025-07-14 | B2: 118.93
A3: 2025-07-21 | B3: 114
A4: 2025-07-28 | B4: 113.4 | C4: Q1 FY26 results + 1:5 split announced
A5: 2025-08-04 | B5: 115.38 | C5: Q1 FY26 results + 1:5 split announced
A6: 2025-08-11 | B6: 116.81
A7: 2025-08-18 | B7: 118.86
A8: 2025-08-25 | B8: 120.13
A9: 2025-09-01 | B9: 121.94
A10: 2025-09-08 | B10: 129.71
A11: 2025-09-15 | B11: 141.88
A12: 2025-09-22 | B12: 146.25 | C12: 1:5 stock split effective
A13: 2025-09-29 | B13: 147.38
A14: 2025-10-06 | B14: 149.7
A15: 2025-10-13 | B15: 165.98
A16: 2025-10-20 | B16: 167.72
A17: 2025-10-27 | B17: 157.85 | C17: Q2 FY26 results; 4.5 GW new PPAs
A18: 2025-11-03 | B18: 151.48 | C18: Q2 FY26 results; 4.5 GW new PPAs
A19: 2025-11-10 | B19: 153.91 | C19: Assam 3,200 MW LoA (~₹48,000cr)
A20: 2025-11-17 | B20: 149.12 | C20: Assam 3,200 MW LoA (~₹48,000cr)
A21: 2025-11-24 | B21: 147.49 | C21: JPVL resolution plan creditor approval
A22: 2025-12-01 | B22: 143.78
A23: 2025-12-08 | B23: 144.49
A24: 2025-12-15 | B24: 141.76
A25: 2025-12-22 | B25: 142.19
A26: 2025-12-29 | B26: 148.17
A27: 2026-01-05 | B27: 141.68
A28: 2026-01-12 | B28: 142.63
A29: 2026-01-19 | B29: 132.96
A30: 2026-01-26 | B30: 132.85
A31: 2026-02-02 | B31: 152.74
A32: 2026-02-09 | B32: 139.9 | C32: Adani Atomic Energy incorporated
A33: 2026-02-16 | B33: 142.7 | C33: Adani Atomic Energy incorporated
A34: 2026-02-23 | B34: 140.11
A35: 2026-03-02 | B35: 138.99
A36: 2026-03-09 | B36: 146.57 | C36: NCLT approves JPVL plan
A37: 2026-03-16 | B37: 151.54 | C37: NCLT approves JPVL plan
A38: 2026-03-23 | B38: 153.92
A39: 2026-03-30 | B39: 159.97
A40: 2026-04-06 | B40: 175.81
...

Sheet 13_Sources_and_Gaps
A1: 13. Sources & Data Gaps — READ BEFORE SUBMITTING
A5: Methodology
A6: This workbook was built using automated web search (news wires, brokerage research notes, exchange press releases, and secondary financial-data aggregators such as Trendlyne, ScanX, HDFC Sky, Business Standard, BusinessToday, Equitymaster) inside a sandboxed research session. Direct scripted/API access to the PRIMARY sources you were asked to use — screener.in, moneycontrol.com, NSE India (nseindia.com), BSE India (bseindia.com), and the companies' own Annual Report PDFs (adanipower.com, tatapower.com, torrentpower.com) — was blocked (HTTP 403) for automated fetches in this environment. All numbers not otherwise flagged therefore come from search-engine snippets of secondary coverage of those primary sources, not the primary documents themselves. UPDATE: the user subsequently uploaded the companies' actual Integrated Annual Report PDFs, and the analysis window was then NARROWED TO FY22-FY26 (the last five fiscal years) at the user's request — earlier-year data has been removed from this workbook. Within FY22-FY26, the consolidated Revenue/Total Income, PAT and Total Assets series (Sheet 2), the Ind AS 108 segment tables (Sheet 6), the AOC-1 group structure (Sheets 7-8) and the Investments detail (Sheet 9) are all PRIMARY-VERIFIED from the audited Annual Reports stored in this repo. Only the FY-end share-price rows in Sheet 2 remain to be filled (from NSE/Yahoo historical data).
A13: Consolidated-vs-Standalone audit (line-by-line re-verification)
