Workbook

Sheet Introduction
A1: INTRODUCTION
A2: Main Company | F2: Competitor
A3: Radico Khaitan Ltd | F3: United Spirits Ltd

Sheet Sales Trend
A1: Trend in Sales
A3: Radico Khaitan Ltd.
A4: Year | B4: 45741 | C4: 46105 | D4: 46104 | E4: 46103 | F4: 46102
A5: Net Sales (Rs. In crores) | B5: 4851.2 | C5: 4118.5 | D5: 3142.8 | E5: 2868 | F5: 2398.8
A6: YOY Sales Growth | B6: =(B5-C5)/C5 -> 0.17790458 | C6: =(C5-D5)/D5 -> 0.31045564 | D6: =(D5-E5)/E5 -> 0.0958159 | E6: =(E5-F5)/F5 -> 0.1955978 | F6: -
A9: United Spirits Ltd.
A10: Year | B10: 45741 | C10: 46105 | D10: 46104 | E10: 46103 | F10: 46102
A11: Net Sales (Rs. In crores) | B11: 11573 | C11: 10692 | D11: 10373.7 | E11: 9423.7 | F11: 9405.5
A12: YOY Sales Growth | B12: =(B11-C11)/C11 -> 0.082398055 | C12: =(C11-D11)/D11 -> 0.030683363 | D12: =(D11-E11)/E11 -> 0.10080966 | E12: =(E11-F11)/F11 -> 0.001935038 | F12: -

Sheet Asset Growth Rate
A1: ASSET GROWTH RATE
A2: Radico Khaitan Ltd.
A3: Year | B3: 45741 | C3: 46105 | D3: 46104 | E3: 46103 | F3: 46102
A4: Total Assets(in Cr) | B4: 4638.956 | C4: 4094.983 | D4: 3719.088 | E4: 2781.192 | F4: 2714.362
A5: YOY Growth | B5: =(B4-C4)/C4 -> 0.13283889 | C5: =(C4-D4)/D4 -> 0.10107182 | D5: =(D4-E4)/E4 -> 0.33722807 | E5: =(E4-F4)/F4 -> 0.024620887 | F5: -
A8: United Spirits Ltd.
A9: Year | B9: 45741 | C9: 46105 | D9: 46104 | E9: 46103 | F9: 46102
A10: Total Assets(in Cr) | B10: 13248 | C10: 11249 | D10: 9761.5 | E10: 8911.3 | F10: 8537
A11: YOY Growth | B11: =(B10-C10)/C10 -> 0.17770468 | C11: =(C10-D10)/D10 -> 0.15238437 | D11: =(D10-E10)/E10 -> 0.095406955 | E11: =(E10-F10)/F10 -> 0.043844442 | F11: -

Sheet Profit
A1: PROFIT OVER THE YEARS
A2: TOTAL PROFIT(in Millions)
B3: 2020-21 | C3: 2021-22 | D3: 2022-23 | E3: 2023-24 | F3: 2024-25 | G3: YOY
A4: Radico Khaitan | B4: 2705.64 | C4: 2485.43 | D4: 2043.72 | E4: 2621.75 | F4: 3456.11 | G4: =(F4-E4)/E4 -> 0.31824545
A5: YoY Sales Growth% (Radico) | B5: - | C5: =(C4-B4)/B4 -> -0.081389246 | D5: =(D4-C4)/C4 -> -0.17771975 | E5: =(E4-D4)/D4 -> 0.28283229 | F5: =(F4-E4)/E4 -> 0.31824545
A6: United Spirits Limited(USL) | B6: 3621 | C6: 8106 | D6: 11258 | E6: 14080 | F6: 15820 | G6: =(F6-E6)/E6 -> 0.12357955
A7: YoY Sales Growth% (USL) | B7: - | C7: =(C6-B6)/B6 -> 1.2386081 | D7: =(D6-C6)/C6 -> 0.38884777 | E7: =(E6-D6)/D6 -> 0.25066619 | F7: =(F6-E6)/E6 -> 0.12357955

Sheet Performance
A1: PERFORMANCE ANALYSIS
A3: TOTAL EMPLOYEES
B4: 2020-21 | C4: 2021-22 | D4: 2022-23 | E4: 2023-24 | F4: 2024-25 | G4: YOY
A5: Radico Khaitan | B5: 1179 | C5: 1196 | D5: 1329 | E5: 1469 | F5: 1494 | G5: =(F5-E5)/E5 -> 0.01701838
A6: YoY Growth% (Radico) | B6: - | C6: =(C5-B5)/B5 -> 0.014418999 | D6: =(D5-C5)/C5 -> 0.11120401 | E6: =(E5-D5)/D5 -> 0.10534236 | F6: =(F5-E5)/E5 -> 0.01701838
A7: United Spirits Limited(USL) | B7: 3261 | C7: 3145 | D7: 2957 | E7: 2598 | F7: 2420 | G7: =(F7-E7)/E7 -> -0.068514242 | M7: ←
A8: YoY Growth% (USL) | B8: - | C8: =(C7-B7)/B7 -> -0.03557191 | D8: =(D7-C7)/C7 -> -0.059777424 | E8: =(E7-D7)/D7 -> -0.12140683 | F8: =(F7-E7)/E7 -> -0.068514242
A10: TOTAL SALES(in crores)
B11: 2020-21 | C11: 2021-22 | D11: 2022-23 | E11: 2023-24 | F11: 2024-25 | G11: YOY
A12: Radico Khaitan | B12: 2398.8 | C12: 2868 | D12: 3142.8 | E12: 4118.5 | F12: 4851.2 | G12: =(F12-E12)/E12 -> 0.17790458
A13: YoY Sales Growth% (Radico) | B13: - | C13: =(C12-B12)/B12 -> 0.1955978 | D13: =(D12-C12)/C12 -> 0.0958159 | E13: =(E12-D12)/D12 -> 0.31045564 | F13: =(F12-E12)/E12 -> 0.17790458
A14: United Spirits Limited(USL) | B14: 9405.5 | C14: 9423.7 | D14: 10373.7 | E14: 10692 | F14: 11573 | G14: =(F14-E14)/E14 -> 0.082398055
A15: YoY Sales Growth% (USL) | B15: - | C15: =(C14-B14)/B14 -> 0.001935038 | D15: =(D14-C14)/C14 -> 0.10080966 | E15: =(E14-D14)/D14 -> 0.030683363 | F15: =(F14-E14)/E14 -> 0.082398055
A17: TOTAL PROFIT(in Millions)
B18: 2020-21 | C18: 2021-22 | D18: 2022-23 | E18: 2023-24 | F18: 2024-25 | G18: YOY
A19: Radico Khaitan | B19: 2705.64 | C19: 2485.43 | D19: 2043.72 | E19: 2621.75 | F19: 3456.11 | G19: =(F19-E19)/E19 -> 0.31824545
A20: YoY Sales Growth% (Radico) | B20: - | C20: =(C19-B19)/B19 -> -0.081389246 | D20: =(D19-C19)/C19 -> -0.17771975 | E20: =(E19-D19)/D19 -> 0.28283229 | F20: =(F19-E19)/E19 -> 0.31824545 | M20: ←
A21: United Spirits Limited(USL) | B21: 3621 | C21: 8106 | D21: 11258 | E21: 14080 | F21: 15820 | G21: =(F21-E21)/E21 -> 0.12357955
A22: YoY Sales Growth% (USL) | B22: - | C22: =(C21-B21)/B21 -> 1.2386081 | D22: =(D21-C21)/C21 -> 0.38884777 | E22: =(E21-D21)/D21 -> 0.25066619 | F22: =(F21-E21)/E21 -> 0.12357955
A24: TOTAL ASSET(in Millions)
B25: 2020-21 | C25: 2021-22 | D25: 2022-23 | E25: 2023-24 | F25: 2024-25 | G25: YOY
A26: Radico Khaitan | B26: 27143.62 | C26: 27811.92 | D26: 37190.88 | E26: 40949.83 | F26: 46389.56 | G26: =(F26-E26)/E26 -> 0.13283889
A27: YoY Sales Growth% (Radico) | B27: - | C27: =(C26-B26)/B26 -> 0.024620887 | D27: =(D26-C26)/C26 -> 0.33722807 | E27: =(E26-D26)/D26 -> 0.10107182 | F27: =(F26-E26)/E26 -> 0.13283889
A28: United Spirits Limited(USL) | B28: 85370 | C28: 89113 | D28: 97615 | E28: 112490 | F28: 132480 | G28: =(F28-E28)/E28 -> 0.17770468
A29: YoY Sales Growth% (USL) | B29: - | C29: =(C28-B28)/B28 -> 0.043844442 | D29: =(D28-C28)/C28 -> 0.095406955 | E29: =(E28-D28)/D28 -> 0.15238437 | F29: =(F28-E28)/E28 -> 0.17770468
M37: ←
M52: ←

Sheet Sales per rupee of asset deploy
A1: Sales per rupee of asset deployed in the company
A5: Asset Turnover Ratio = Net sales / Total Assets
A7: Radico Khaitan Ltd.
B8: 45741 | C8: 46105 | D8: 46104 | E8: 46103 | F8: 46102
A9: Net Sales (in Cr) | B9: 4851.2 | C9: 4118.5 | D9: 3142.8 | E9: 2868 | F9: 2398.8
A10: Total Assets (in CR) | B10: 4638.956 | C10: 4094.983 | D10: 3719.088 | E10: 2781.192 | F10: 2714.362
A11: Sales per rupee of asset deployed | B11: =B9/B10 -> 1.0457525 | C11: =C9/C10 -> 1.0057429 | D11: =D9/D10 -> 0.84504588 | E11: =E9/E10 -> 1.0312125 | F11: =F9/F10 -> 0.88374358
A13: United Spirits Ltd.
B14: 45741 | C14: 46105 | D14: 46104 | E14: 46103 | F14: 46102
A15: Net Sales (in Cr) | B15: 11573 | C15: 10692 | D15: 10373.7 | E15: 9423.7 | F15: 9405.5
A16: Total Assets (in CR) | B16: 13248 | C16: 11249 | D16: 9761.5 | E16: 8911.3 | F16: 8537
A17: Sales per rupee of asset deployed | B17: =B15/B16 -> 0.87356582 | C17: =C15/C16 -> 0.95048449 | D17: =D15/D16 -> 1.0627158 | E17: =E15/E16 -> 1.0575 | F17: =F15/F16 -> 1.1017336

Sheet Sales per employee
A1: Sales per employee
A5: Net sales / Total no. of employees
A7: Radico Khaitan Ltd.
B8: 45741 | C8: 46105 | D8: 46104 | E8: 46103 | F8: 46102
A9: Net Sales (in Cr) | B9: 4851.2 | C9: 4118.5 | D9: 3142.8 | E9: 2868 | F9: 2398.8
A10: Number of Employees | B10: 1494 | C10: 1469 | D10: 1329 | E10: 1196 | F10: 1179
A11: Sales(in Cr) per employee | B11: =B9/B10 -> 3.2471218 | C11: =C9/C10 -> 2.8036079 | D11: =D9/D10 -> 2.3647856 | E11: =E9/E10 -> 2.3979933 | F11: =F9/F10 -> 2.0346056
A13: United Spirits Ltd.
B14: 45741 | C14: 46105 | D14: 46104 | E14: 46103 | F14: 46102
A15: Net Sales (in Cr) | B15: 11573 | C15: 10692 | D15: 10373.7 | E15: 9423.7 | F15: 9405.5
A16: Number of Employees | B16: 2420 | C16: 2598 | D16: 2957 | E16: 3145 | F16: 3261
A17: Sales(in Cr) per employee | B17: =B15/B16 -> 4.7822314 | C17: =C15/C16 -> 4.1154734 | D17: =D15/D16 -> 3.508184 | E17: =E15/E16 -> 2.996407 | F17: =F15/F16 -> 2.884238

Sheet GPPM
A1: Liquor Industry Competitor Analysis (FY2021 - FY2025)
A3: 5-Year Growth Performance Profile Matrix
A4: Growth Dimension | B4: Radico Khaitan Ltd. | C4: United Spirits Ltd. (USL) | D4: Strategic Market Dynamics
A5: Sales Growth | B5: Robust volume expansion driven by high-velocity premium brands (Magic Moments, Morpheus). | C5: Flat headline growth due to divestment of low-margin popular brands; premium segments expanded heavily. | D5: USL prioritized premium value margins over volume; Radico pursued concurrent volume and brand premiumization.
A6: Assets Growth | B6: High asset expansion. Massive capital expenditure deployed on backward integration (e.g., Sitapur plant). | C6: Controlled and asset-light. Corporate restructuring optimized manufacturing footprint. | D6: Radico built physical capacity to secure raw spirit supplies; USL enhanced capital returns by reducing asset weight.
A7: Profit Growth | B7: Steady absolute growth, though short-term margins faced inflationary pressures from glass and grain inputs. | C7: Superior margin expansion. Divestment of regular portfolio significantly improved overall EBITDA profiles. | D7: USL underwent structural margin expansion; Radico focused on scaling long-term volume capabilities.
A8: Market Price Growth | B8: Massive multi-bagger returns, strongly re-rated for entering luxury single malts and craft segments. | C8: Exceptional market capitalization growth, matching valuation standards of a pure global Diageo clone. | D8: Both businesses rewarded intensely by public markets for transitioning into pure-play premium narratives.
A11: Visual Trend Reference Blocks
A13: Year | B13: Radico Asset Turnover | C13: USL Asset Turnover
A14: FY21 | B14: ='Financial Data'!E5 -> 0.88374358 | C14: ='Financial Data'!E14 -> 1.1017336
A15: FY22 | B15: ='Financial Data'!E6 -> 1.0312125 | C15: ='Financial Data'!E15 -> 1.0575
A16: FY23 | B16: ='Financial Data'!E7 -> 0.84504588 | C16: ='Financial Data'!E16 -> 1.0627158
A17: FY24 | B17: ='Financial Data'!E8 -> 1.0057429 | C17: ='Financial Data'!E17 -> 0.95048449
A18: FY25 | B18: ='Financial Data'!E9 -> 1.0457525 | C18: ='Financial Data'!E18 -> 0.87356582
A21: Year | B21: Radico Sales/Emp | C21: USL Sales/Emp
A22: FY21 | B22: ='Financial Data'!F5 -> 2.0346056 | C22: ='Financial Data'!F14 -> 2.884238
A23: FY22 | B23: ='Financial Data'!F6 -> 2.3979933 | C23: ='Financial Data'!F15 -> 2.996407
A24: FY23 | B24: ='Financial Data'!F7 -> 2.364936 | C24: ='Financial Data'!F16 -> 3.508184
A25: FY24 | B25: ='Financial Data'!F8 -> 2.8032675 | C25: ='Financial Data'!F17 -> 4.1154734
A26: FY25 | B26: ='Financial Data'!F9 -> 3.2471218 | C26: ='Financial Data'!F18 -> 4.7822314

Sheet Financial Data
A1: Detailed Financial Efficiency Analysis & Calculations
A3: Radico Khaitan Ltd. (Operational Metrics)
A4: Fiscal Year | B4: Net Sales (₹ Cr) | C4: Total Assets (₹ Cr) | D4: Estimated Employee Base | E4: Sales per Rupee of Asset | F4: Sales per Employee (₹ Cr)
A5: FY2021 | B5: 2418 | C5: 2500 | D5: 1179 | E5: 0.88374358 | F5: 2.0346056
A6: FY2022 | B6: 2868 | C6: 2810 | D6: 1196 | E6: 1.0312125 | F6: =B6/D6 -> 2.3979933
A7: FY2023 | B7: 3143 | C7: 3420 | D7: 1329 | E7: 0.84504588 | F7: =B7/D7 -> 2.364936
A8: FY2024 | B8: 4118 | C8: 4200 | D8: 1469 | E8: 1.0057429 | F8: =B8/D8 -> 2.8032675
A9: FY2025 | B9: 4600 | C9: 4700 | D9: 1494 | E9: 1.0457525 | F9: 3.2471218
A10: 5-Year Average | B10: =AVERAGE(B5:B9) -> 3429.4 | C10: =AVERAGE(C5:C9) -> 3526 | D10: =AVERAGE(D5:D9) -> 1333.4 | E10: =AVERAGE(E5:E9) -> 0.96229948 | F10: =AVERAGE(F5:F9) -> 2.5695849
B11: 4.7822314 | C11: 4.1154734 | D11: 3.508184 | E11: 2.996407 | F11: 2.884238
A12: United Spirits Ltd. (Diageo India - Operational Metrics)
A13: Fiscal Year | B13: Net Sales (₹ Cr) | C13: Total Assets (₹ Cr) | D13: Estimated Employee Base | E13: Sales per Rupee of Asset | F13: Sales per Employee (₹ Cr)
A14: FY2021 | B14: 8131 | C14: 7200 | D14: 3261 | E14: 1.1017336 | F14: 2.884238
A15: FY2022 | B15: 9382 | C15: 7500 | D15: 3145 | E15: 1.0575 | F15: 2.996407
A16: FY2023 | B16: 10374 | C16: 6820 | D16: 2957 | E16: 1.0627158 | F16: 3.508184
A17: FY2024 | B17: 10611 | C17: 7220 | D17: 2598 | E17: 0.95048449 | F17: 4.1154734
A18: FY2025 | B18: 11200 | C18: 7600 | D18: 2420 | E18: 0.87356582 | F18: 4.7822314
A19: 5-Year Average | B19: =AVERAGE(B14:B18) -> 9939.6 | C19: =AVERAGE(C14:C18) -> 7268 | D19: =AVERAGE(D14:D18) -> 2876.2 | E19: =AVERAGE(E14:E18) -> 1.0091999 | F19: =AVERAGE(F14:F18) -> 3.6573068

Sheet Major acquisitions and their im
A1: DETAILS | B1: SALES IMPACT | C1: PROFIT IMPACT | D1: CASH FROM OPERATIONS
A2: Radico Khaitan Limited:
A3: In a major move into luxury and lifestyle spirits, Radico approved a strategic investment of up to ₹40 crore to acquire a 47.5% equity stake in both D'YAVOL Spirits B.V. (Netherlands) and D'YAVOL Spirits Private Limited (India). This high-profile partnership alongside Shah Rukh Khan, Aryan Khan, and Nikhil Kamath positions Radico as the largest shareholder in the brand to roll out luxury tequila and luxury spirits globally. | B3: It being a new partial stakeholding acquistion by Radico Khaitan in a premium tequilla Brand rolled out by Aryan Khan, Shah Rukh Khan and Nikhil Kamath, the impact on sales has not been major being just a small part of Radico's portfolio. However the sales(consolidated) of Radico Khaitan in Financial Year 2026 has gone up from the previous financial year by almost 24% year over year. The deal has been more of a strategic move to expand globally in the premium spirts segment with the Godwill and brand image of the famous bollywood actor and one of the famous Business leader Nikhil. | C3: The major stakeholding takeover has not have had a major impact on the profit of Radico Khaitan yet. But the firm has seen a net profit rise by approximately~75% YoY that is from 304.5 crores to 604.4 crores in FY 26. Hence can per say that the strategic investments have helped firm expand their business, higher the sales and earn more profit out of premiumisation. | D3: Although Radico Khaitan's cash flow has improved significantly in Financial Year 26, the impact of this investment activity is very small on the books of accounts. Bringing in around 5.5 crores of net cash inflows from operations.
A4: Consolidation via Radico Spiritzs (2022)
A5: Radico acquired a 100% equity stake in Radico Spiritzs India Private Limited, turning it into a wholly-owned subsidiary. Through this vehicle, Radico layered in full ownership of several real estate and construction entities (including Accomreal Builders and Compaqt Era Builders) to streamline corporate assets. | B5: Radico Khaitan has reported in their reports that this acquisition was purely made to improve and assist the operations of their real estate entity. Hence the consolidated level impact of sales is not visible and impactful. | C5: As Radico Khaitan Spiritz business is anciliary to the real estate the profit impact of the real estate business is not direct to the spirits business. | D5: There was an investing cash outflow but no impact on cash flows from operations as they are filling to seperate entities.
A6: United Spirits Limited
A7: In 2025, United Spirits (part of Diageo) acquired NAO Spirits, a leading Indian craft gin company known for its premium and artisanal gin brands. This acquisition was aimed at strengthening USL’s presence in the fast-growing craft spirits segment, particularly gin, which is seeing strong demand among urban and younger consumers. The move aligns with Diageo’s global strategy of premiumisation, where the focus is on high-margin, experience-driven alcohol categories rather than mass-market volumes. By acquiring NAO Spirits, USL has expanded its premium portfolio and strengthened its position in niche but high-growth categories. | B7: NAO’s standalone net turnover was ₹34.83 crore in FY24; after acquisition NAO becomes a subsidiary so its full revenue will be consolidated into United Spirits,but the company did not claim an immediate material uplifting impact to USL’s overall sales given NAO’s small scale compared to USL overall business. | C7: As the stake increased to 97.07% of United Spirits in NAO spirits, now NAO being the subsidary, the profit and revenue would add up to the consolidated financial statements hence creating a positive impact on the profit of the business. But USL being a multi-diversified business the impact of NAO is not a large scale impact. | D7: The cash flows from operations do not have a major inflows as of now, but in further quarters there would be inflows and cash outflows from Operations of NAO Spirits.

Sheet Shareholding patterns
A1: Radico Khaitan Ltd.
A2: Category of Shareholder | B2: 45901 | C2: 46082 | D2: Change (Mar 26 vs Sep 25)
A3: Promoter & Promoter Group Shareholders | B3: 10 | C3: 8 | D3: -2
A4: Promoter Shares Held | B4: 53829818 | C4: 53829818 | D4: No Change
A5: Promoter Holding (%) | B5: 0.4021 | C5: 0.402 | D5: -0.01 pp
A6: Public Shareholders | B6: 149241 | C6: 152028 | D6: =2787 -> 2787
A7: Public Shares Held | B7: 80047728 | C7: 80068115 | D7: 20387
A8: Public Holding (%) | B8: 0.5979 | C8: 0.598 | D8: 76161
A28: United Spirits Limited
A29: Category of Shareholder | B29: 45901 | C29: 46082 | D29: Change (Mar 26 vs Sep 25)
A30: Promoter & Promoter Group Shareholders | B30: 4 | C30: 4 | D30: No Change
A31: Promoter & Promoter Group Shares Held | B31: 4,12,22,410 | C31: 4,12,22,410 | D31: No Change
A32: Promoter Holding (%) | B32: 0.5667 | C32: 0.5667 | D32: No Change
A33: Public Shareholders | B33: 2,92,657 | C33: 3,23,934 | D33: 31277
A34: Public Shares Held | B34: 3,15,29,443 | C34: 3,15,29,443 | D34: No Change
A35: Public Holding (%) | B35: 0.4333 | C35: 0.4333 | D35: No Change

Sheet Shareholders Report Radico
A1: Number | B1: Investor Name | C1: % Outstanding | AB1: Position (M) | BA1: Position Change (M) | BZ1: Value ($, M) | CY1: Filing Date | DX1: Filing Source | EW1: Investor Type | EX1: Investor Sub-Type | EY1: Equity Assets ($, M) | EZ1: Investment Style | FA1: Turnover | FZ1: City | GA1: Country/Region
C2: Most Recent | D2: 46142 | E2: 46112 | F2: 46081 | G2: 46053 | H2: 46022 | I2: 45991 | J2: 45961 | K2: 45930 | L2: 45900 | M2: 45869 | N2: 45838 | O2: 45808 | P2: 45777 | Q2: 45747 | R2: 45716 | S2: 45688 | T2: 45657 | U2: 45626 | V2: 45596 | W2: 45565 | X2: 45535 | Y2: 45504 | Z2: 45473 | AA2: 45443 | AB2: Most Recent | AC2: 46142 | AD2: 46112 | AE2: 46081 | AF2: 46053 | AG2: 46022 | AH2: 45991 | AI2: 45961 | AJ2: 45930 | AK2: 45900 | AL2: 45869 | AM2: 45838 | AN2: 45808 | AO2: 45777 | AP2: 45747 | AQ2: 45716 | AR2: 45688 | AS2: 45657 | AT2: 45626 | AU2: 45596 | AV2: 45565 | AW2: 45535 | AX2: 45504 | AY2: 45473 | AZ2: 45443 | BA2: Most Recent | BB2: 46142 | BC2: 46112 | BD2: 46081 | BE2: 46053 | BF2: 46022 | BG2: 45991 | BH2: 45961 | BI2: 45930 | BJ2: 45900 | BK2: 45869 | BL2: 45838 | BM2: 45808 | BN2: 45777 | BO2: 45747 | BP2: 45716 | BQ2: 45688 | BR2: 45657 | BS2: 45626 | BT2: 45596 | BU2: 45565 | BV2: 45535 | BW2: 45504 | BX2: 45473 | BY2: 45443 | BZ2: Most Recent | CA2: 46142 | CB2: 46112 | CC2: 46081 | CD2: 46053 | CE2: 46022 | CF2: 45991 | CG2: 45961 | CH2: 45930 | CI2: 45900 | CJ2: 45869 | CK2: 45838 | CL2: 45808 | CM2: 45777 | CN2: 45747 | CO2: 45716 | CP2: 45688 | CQ2: 45657 | CR2: 45626 | CS2: 45596 | CT2: 45565 | CU2: 45535 | CV2: 45504 | CW2: 45473 | CX2: 45443 | CY2: Most Recent | CZ2: 46142 | DA2: 46112 | DB2: 46081 | DC2: 46053 | DD2: 46022 | DE2: 45991 | DF2: 45961 | DG2: 45930 | DH2: 45900 | DI2: 45869 | DJ2: 45838 | DK2: 45808 | DL2: 45777 | DM2: 45747 | DN2: 45716 | DO2: 45688 | DP2: 45657 | DQ2: 45626 | DR2: 45596 | DS2: 45565 | DT2: 45535 | DU2: 45504 | DV2: 45473 | DW2: 45443 | DX2: Most Recent | DY2: 46142 | DZ2: 46112 | EA2: 46081 | EB2: 46053 | EC2: 46022 | ED2: 45991 | EE2: 45961 | EF2: 45930 | EG2: 45900 | EH2: 45869 | EI2: 45838 | EJ2: 45808 | EK2: 45777 | EL2: 45747 | EM2: 45716 | EN2: 45688 | EO2: 45657 | EP2: 45626 | EQ2: 45596 | ER2: 45565 | ES2: 45535 | ET2: 45504 | EU2: 45473 | EV2: 45443 | FA2: Most Recent | FB2: 46142 | FC2: 46112 | FD2: 46081 | FE2: 46053 | FF2: 46022 | FG2: 45991 | FH2: 45961 | FI2: 45930 | FJ2: 45900 | FK2: 45869 | FL2: 45838 | FM2: 45808 | FN2: 45777 | FO2: 45747 | FP2: 45716 | FQ2: 45688 | FR2: 45657 | FS2: 45626 | FT2: 45596 | FU2: 45565 | FV2: 45535 | FW2: 45504 | FX2: 45473 | FY2: 45443
A3: 1 | B3: Sapphire Intrex, Ltd. | C3: 0.338824 | D3: 0.338908 | E3: 0.338908 | F3: 0.338919 | G3: 0.338919 | H3: 0.338919 | I3: 0.338919 | J3: 0.33896 | K3: 0.33896 | L3: 0.338985 | M3: 0.338985 | N3: 0.339096 | O3: 0.339096 | P3: 0.339137 | Q3: 0.339137 | R3: 0.339149 | S3: 0.339149 | T3: 0.339187 | U3: 0.339187 | V3: 0.339214 | W3: 0.33925 | X3: 0.33925 | Y3: 0.33925 | Z3: 0.339371 | AA3: 0.339371 | AB3: 45.379098 | AC3: 45.379098 | AD3: 45.379098 | AE3: 45.379098 | AF3: 45.379098 | AG3: 45.379098 | AH3: 45.379098 | AI3: 45.379098 | AJ3: 45.379098 | AK3: 45.379098 | AL3: 45.379098 | AM3: 45.379098 | AN3: 45.379098 | AO3: 45.379098 | AP3: 45.379098 | AQ3: 45.379098 | AR3: 45.379098 | AS3: 45.379098 | AT3: 45.379098 | AU3: 45.379098 | AV3: 45.379098 | AW3: 45.379098 | AX3: 45.379098 | AY3: 45.379098 | AZ3: 45.379098 | BA3: 0 | BB3: 0 | BC3: 0 | BD3: 0 | BE3: 0 | BF3: 0 | BG3: 0 | BH3: 0 | BI3: 0 | BJ3: 0 | BK3: 0 | BL3: 0 | BM3: 0 | BN3: 0 | BO3: 0 | BP3: 0 | BQ3: 0 | BR3: 0 | BS3: 0 | BT3: 0 | BU3: 0 | BV3: 0 | BW3: 0 | BX3: 0 | BY3: 0 | BZ3: 1667.7447 | CA3: 1667.7447 | CB3: 1667.7447 | CC3: 1667.7447 | CD3: 1667.7447 | CE3: 1667.7447 | CF3: 1477.8886 | CG3: 1477.8886 | CH3: 1477.8886 | CI3: 1390.0535 | CJ3: 1390.0535 | CK3: 1390.0535 | CL3: 1287.057 | CM3: 1287.057 | CN3: 1287.057 | CO3: 1383.5013 | CP3: 1383.5013 | CQ3: 1383.5013 | CR3: 1108.2404 | CS3: 1108.2404 | CT3: 1108.2404 | CU3: 972.55701 | CV3: 972.55701 | CW3: 972.55701 | CX3: 940.63414 | CY3: 46022 | CZ3: 46022 | DA3: 46022 | DB3: 46022 | DC3: 46022 | DD3: 46022 | DE3: 45930 | DF3: 45930 | DG3: 45930 | DH3: 45838 | DI3: 45838 | DJ3: 45838 | DK3: 45747 | DL3: 45747 | DM3: 45747 | DN3: 45657 | DO3: 45657 | DP3: 45657 | DQ3: 45565 | DR3: 45565 | DS3: 45565 | DT3: 45473 | DU3: 45473 | DV3: 45473 | DW3: 45382 | DX3: Shareholder Report | DY3: Shareholder Report | DZ3: Shareholder Report | EA3: Shareholder Report | EB3: Shareholder Report | EC3: Shareholder Report | ED3: Shareholder Report | EE3: Shareholder Report | EF3: Shareholder Report | EG3: Shareholder Report | EH3: Shareholder Report | EI3: Shareholder Report | EJ3: Shareholder Report | EK3: Shareholder Report | EL3: Shareholder Report | EM3: Shareholder Report | EN3: Shareholder Report | EO3: Shareholder Report | EP3: Shareholder Report | EQ3: Shareholder Report | ER3: Shareholder Report | ES3: Shareholder Report | ET3: Shareholder Report | EU3: Shareholder Report | EV3: Shareholder Report | EW3: Strategic Entities | EX3: Corporation | EY3: 1684.126 | FA3: Low | FB3: Low | FC3: Low | FD3: Low | FE3: Low | FF3: Low | FG3: Low | FH3: Low | FI3: Low | FJ3: Low | FK3: Low | FL3: Low | FM3: Low | FN3: Low | FO3: Low | FP3: Low | FQ3: Low | FR3: Low | FS3: Low | FT3: Low | FU3: Low | FV3: Low | FW3: Low | FX3: Low | FZ3: Kolkata | GA3: India
A4: 2 | B4: Rampur International, Ltd. | C4: 0.03923 | D4: 0.039239 | E4: 0.039239 | F4: 0.039241 | G4: 0.039241 | H4: 0.039241 | I4: 0.039241 | J4: 0.039245 | K4: 0.039245 | L4: 0.039248 | M4: 0.039248 | N4: 0.039261 | O4: 0.039261 | P4: 0.039266 | Q4: 0.039266 | R4: 0.039267 | S4: 0.039267 | T4: 0.039272 | U4: 0.039272 | V4: 0.039275 | W4: 0.039279 | X4: 0.039279 | Y4: 0.039279 | Z4: 0.039293 | AA4: 0.039293 | AB4: 5.254085 | AC4: 5.254085 | AD4: 5.254085 | AE4: 5.254085 | AF4: 5.254085 | AG4: 5.254085 | AH4: 5.254085 | AI4: 5.254085 | AJ4: 5.254085 | AK4: 5.254085 | AL4: 5.254085 | AM4: 5.254085 | AN4: 5.254085 | AO4: 5.254085 | AP4: 5.254085 | AQ4: 5.254085 | AR4: 5.254085 | AS4: 5.254085 | AT4: 5.254085 | AU4: 5.254085 | AV4: 5.254085 | AW4: 5.254085 | AX4: 5.254085 | AY4: 5.254085 | AZ4: 5.254085 | BA4: 0 | BB4: 0 | BC4: 0 | BD4: 0 | BE4: 0 | BF4: 0 | BG4: 0 | BH4: 0 | BI4: 0 | BJ4: 0 | BK4: 0 | BL4: 0 | BM4: 0 | BN4: 0 | BO4: 0 | BP4: 0 | BQ4: 0 | BR4: 0 | BS4: 0 | BT4: 0 | BU4: 0 | BV4: 0 | BW4: 0 | BX4: 0 | BY4: 0 | BZ4: 193.0949 | CA4: 193.0949 | CB4: 193.0949 | CC4: 193.0949 | CD4: 193.0949 | CE4: 193.0949 | CF4: 171.11298 | CG4: 171.11298 | CH4: 171.11298 | CI4: 160.94325 | CJ4: 160.94325 | CK4: 160.94325 | CL4: 149.0181 | CM4: 149.0181 | CN4: 149.0181 | CO4: 160.18462 | CP4: 160.18462 | CQ4: 160.18462 | CR4: 128.31435 | CS4: 128.31435 | CT4: 128.31435 | CU4: 112.60464 | CV4: 112.60464 | CW4: 112.60464 | CX4: 108.90855 | CY4: 46022 | CZ4: 46022 | DA4: 46022 | DB4: 46022 | DC4: 46022 | DD4: 46022 | DE4: 45930 | DF4: 45930 | DG4: 45930 | DH4: 45838 | DI4: 45838 | DJ4: 45838 | DK4: 45747 | DL4: 45747 | DM4: 45747 | DN4: 45657 | DO4: 45657 | DP4: 45657 | DQ4: 45565 | DR4: 45565 | DS4: 45565 | DT4: 45473 | DU4: 45473 | DV4: 45473 | DW4: 45382 | DX4: Shareholder Report | DY4: Shareholder Report | DZ4: Shareholder Report | EA4: Shareholder Report | EB4: Shareholder Report | EC4: Shareholder Report | ED4: Shareholder Report | EE4: Shareholder Report | EF4: Shareholder Report | EG4: Shareholder Report | EH4: Shareholder Report | EI4: Shareholder Report | EJ4: Shareholder Report | EK4: Shareholder Report | EL4: Shareholder Report | EM4: Shareholder Report | EN4: Shareholder Report | EO4: Shareholder Report | EP4: Shareholder Report | EQ4: Shareholder Report | ER4: Shareholder Report | ES4: Shareholder Report | ET4: Shareholder Report | EU4: Shareholder Report | EV4: Shareholder Report | EW4: Strategic Entities | EX4: Corporation | EY4: 193.0949 | FA4: Low | FB4: Low | FC4: Low | FD4: Low | FE4: Low | FF4: Low | FG4: Low | FH4: Low | FI4: Low | FJ4: Low | FK4: Low | FL4: Low | FM4: Low | FN4: Low | FO4: Low | FP4: Low | FQ4: Low | FR4: Low | FS4: Low | FT4: Low | FU4: Low | FV4: Low | FW4: Low | FX4: Low | FY4: Low | FZ4: New Delhi | GA4: India
A5: 3 | B5: Nippon Life India Asset Management Limited | C5: 0.033643 | D5: 0.033652 | E5: 0.033652 | F5: 0.033653 | G5: 0.033653 | H5: 0.033653 | I5: 0.034118 | J5: 0.034122 | K5: 0.034122 | L5: 0.033954 | M5: 0.033954 | N5: 0.033965 | O5: 0.033952 | P5: 0.033956 | Q5: 0.033956 | R5: 0.033798 | S5: 0.033798 | T5: 0.033802 | U5: 0.033554 | V5: 0.033556 | W5: 0.03356 | X5: 0.033539 | Y5: 0.033522 | Z5: 0.033501 | AA5: 0.031236 | AB5: 4.505876 | AC5: 4.505876 | AD5: 4.505876 | AE5: 4.505876 | AF5: 4.505876 | AG5: 4.505876 | AH5: 4.568193 | AI5: 4.568193 | AJ5: 4.568193 | AK5: 4.545307 | AL5: 4.545307 | AM5: 4.545307 | AN5: 4.543547 | AO5: 4.543547 | AP5: 4.543547 | AQ5: 4.522315 | AR5: 4.522315 | AS5: 4.522315 | AT5: 4.489057 | AU5: 4.489057 | AV5: 4.489057 | AW5: 4.486325 | AX5: 4.484041 | AY5: 4.479541 | AZ5: 4.176719 | BA5: 0 | BB5: 0 | BC5: 0 | BD5: 0 | BE5: 0 | BF5: -0.062317 | BG5: 0 | BH5: 0 | BI5: 0.022886 | BJ5: 0 | BK5: 0 | BL5: 0.00176 | BM5: 0 | BN5: 0 | BO5: 0.021232 | BP5: 0 | BQ5: 0 | BR5: 0.033258 | BS5: 0 | BT5: 0 | BU5: 0.002732 | BV5: 0.002284 | BW5: 0.0045 | BX5: 0.302822 | BY5: 0.003332 | BZ5: 165.59718 | CA5: 165.59718 | CB5: 165.59718 | CC5: 165.59718 | CD5: 165.59718 | CE5: 165.59718 | CF5: 148.77512 | CG5: 148.77512 | CH5: 148.77512 | CI5: 139.23195 | CJ5: 139.23195 | CK5: 139.23195 | CL5: 128.86558 | CM5: 128.86558 | CN5: 128.86558 | CO5: 137.87468 | CP5: 137.87468 | CQ5: 137.87468 | CR5: 109.63097 | CS5: 109.63097 | CT5: 109.63097 | CU5: 103.88672 | CV5: 92.333555 | CW5: 96.004751 | CX5: 78.929295 | CY5: 46022 | CZ5: 46022 | DA5: 46022 | DB5: 46022 | DC5: 46022 | DD5: 46022 | DE5: 45930 | DF5: 45930 | DG5: 45930 | DH5: 45838 | DI5: 45838 | DJ5: 45838 | DK5: 45747 | DL5: 45747 | DM5: 45747 | DN5: 45657 | DO5: 45657 | DP5: 45657 | DQ5: 45565 | DR5: 45565 | DS5: 45565 | DT5: 45535 | DU5: 45504 | DV5: 45473 | DW5: 45443 | DX5: Shareholder Report | DY5: Shareholder Report | DZ5: Shareholder Report | EA5: Shareholder Report | EB5: Shareholder Report | EC5: Shareholder Report | ED5: Shareholder Report | EE5: Shareholder Report | EF5: Shareholder Report | EG5: Shareholder Report | EH5: Shareholder Report | EI5: Shareholder Report | EJ5: Shareholder Report | EK5: Shareholder Report | EL5: Shareholder Report | EM5: Shareholder Report | EN5: Shareholder Report | EO5: Shareholder Report | EP5: Shareholder Report | EQ5: Shareholder Report | ER5: Shareholder Report | ES5: Aggregate MFs | ET5: Aggregate MFs | EU5: Aggregate MFs | EV5: Aggregate MFs | EW5: Investment Managers | EX5: Investment Advisor | EY5: 54373.575 | EZ5: Core Growth | FA5: Low | FB5: Low | FC5: Low | FD5: Low | FE5: Low | FF5: Low | FG5: Low | FH5: Low | FI5: Low | FJ5: Low | FK5: Low | FL5: Low | FM5: Low | FN5: Low | FO5: Low | FP5: Low | FQ5: Low | FR5: Low | FS5: Low | FT5: Low | FU5: Low | FV5: Low | FW5: Low | FX5: Low | FY5: Low | FZ5: Mumbai | GA5: India
A6: 4 | B6: Tata Asset Management Ltd. | C6: 0.032837 | D6: 0.032845 | E6: 0.032845 | F6: 0.032846 | G6: 0.032846 | H6: 0.032846 | I6: 0.034141 | J6: 0.034145 | K6: 0.034145 | L6: 0.044901 | M6: 0.044901 | N6: 0.044916 | O6: 0.046101 | P6: 0.046107 | Q6: 0.046107 | R6: 0.046675 | S6: 0.046675 | T6: 0.046681 | U6: 0.052784 | V6: 0.052788 | W6: 0.052794 | X6: 0.055879 | Y6: 0.055879 | Z6: 0.055899 | AA6: 0.056017 | AB6: 4.39785 | AC6: 4.39785 | AD6: 4.39785 | AE6: 4.39785 | AF6: 4.39785 | AG6: 4.39785 | AH6: 4.571255 | AI6: 4.571255 | AJ6: 4.571255 | AK6: 6.010793 | AL6: 6.010793 | AM6: 6.010793 | AN6: 6.169453 | AO6: 6.169453 | AP6: 6.169453 | AQ6: 6.245312 | AR6: 6.245312 | AS6: 6.245312 | AT6: 7.061882 | AU6: 7.061882 | AV6: 7.061882 | AW6: 7.474539 | AX6: 7.474539 | AY6: 7.474539 | AZ6: 7.490339 | BA6: 0 | BB6: 0 | BC6: 0 | BD6: 0 | BE6: 0 | BF6: -0.173405 | BG6: 0 | BH6: 0 | BI6: -1.439538 | BJ6: 0 | BK6: 0 | BL6: -0.15866 | BM6: 0 | BN6: 0 | BO6: -0.075859 | BP6: 0 | BQ6: 0 | BR6: -0.81657 | BS6: 0 | BT6: 0 | BU6: -0.412657 | BV6: 0 | BW6: 0 | BX6: -0.0158 | BY6: 0 | BZ6: 161.62708 | CA6: 161.62708 | CB6: 161.62708 | CC6: 161.62708 | CD6: 161.62708 | CE6: 161.62708 | CF6: 148.87484 | CG6: 148.87484 | CH6: 148.87484 | CI6: 184.12275 | CJ6: 184.12275 | CK6: 184.12275 | CL6: 174.98007 | CM6: 174.98007 | CN6: 174.98007 | CO6: 190.40478 | CP6: 190.40478 | CQ6: 190.40478 | CR6: 172.46405 | CS6: 172.46405 | CT6: 172.46405 | CU6: 160.19303 | CV6: 160.19303 | CW6: 160.19303 | CX6: 155.26242 | CY6: 46022 | CZ6: 46022 | DA6: 46022 | DB6: 46022 | DC6: 46022 | DD6: 46022 | DE6: 45930 | DF6: 45930 | DG6: 45930 | DH6: 45838 | DI6: 45838 | DJ6: 45838 | DK6: 45747 | DL6: 45747 | DM6: 45747 | DN6: 45657 | DO6: 45657 | DP6: 45657 | DQ6: 45565 | DR6: 45565 | DS6: 45565 | DT6: 45473 | DU6: 45473 | DV6: 45473 | DW6: 45382 | DX6: Shareholder Report | DY6: Shareholder Report | DZ6: Shareholder Report | EA6: Shareholder Report | EB6: Shareholder Report | EC6: Shareholder Report | ED6: Shareholder Report | EE6: Shareholder Report | EF6: Shareholder Report | EG6: Shareholder Report | EH6: Shareholder Report | EI6: Shareholder Report | EJ6: Shareholder Report | EK6: Shareholder Report | EL6: Shareholder Report | EM6: Shareholder Report | EN6: Shareholder Report | EO6: Shareholder Report | EP6: Shareholder Report | EQ6: Shareholder Report | ER6: Shareholder Report | ES6: Shareholder Report | ET6: Shareholder Report | EU6: Shareholder Report | EV6: Shareholder Report | EW6: Investment Managers | EX6: Investment Advisor | EY6: 15766.072 | EZ6: Growth | FA6: Moderate | FB6: Moderate | FC6: Moderate | FD6: Moderate | FE6: Moderate | FF6: Moderate | FG6: Moderate | FH6: Moderate | FI6: Moderate | FJ6: Low | FK6: Low | FL6: Low | FM6: Low | FN6: Low | FO6: Low | FP6: Low | FQ6: Low | FR6: Low | FS6: Low | FT6: Low | FU6: Low | FV6: Low | FW6: Low | FX6: Moderate | FY6: Moderate | FZ6: Mumbai | GA6: India
A7: 5 | B7: Kotak Mahindra Asset Management Company Limited | C7: 0.029466 | D7: 0.029474 | E7: 0.029474 | F7: 0.029475 | G7: 0.029475 | H7: 0.029475 | I7: 0.029761 | J7: 0.029765 | K7: 0.029765 | L7: 0.028196 | M7: 0.028196 | N7: 0.028206 | O7: 0.028195 | P7: 0.028198 | Q7: 0.028198 | R7: 0.025427 | S7: 0.024284 | T7: 0.024208 | U7: 0.020284 | V7: 0.020282 | W7: 0.020195 | X7: 0.020272 | Y7: 0.020047 | Z7: 0.020047 | AA7: 0.019778 | AB7: 3.946477 | AC7: 3.946477 | AD7: 3.946477 | AE7: 3.946477 | AF7: 3.946477 | AG7: 3.946477 | AH7: 3.984849 | AI7: 3.984849 | AJ7: 3.984849 | AK7: 3.774575 | AL7: 3.774575 | AM7: 3.774575 | AN7: 3.773096 | AO7: 3.773096 | AP7: 3.773096 | AQ7: 3.402258 | AR7: 3.249263 | AS7: 3.238673 | AT7: 2.713714 | AU7: 2.713273 | AV7: 2.701342 | AW7: 2.711658 | AX7: 2.681489 | AY7: 2.680616 | AZ7: 2.644653 | BA7: 0 | BB7: 0 | BC7: 0 | BD7: 0 | BE7: 0 | BF7: -0.038372 | BG7: 0 | BH7: 0 | BI7: 0.210274 | BJ7: 0 | BK7: 0 | BL7: 0.001479 | BM7: 0 | BN7: 0 | BO7: 0.370838 | BP7: 0.152995 | BQ7: 0.01059 | BR7: 0.524959 | BS7: 0.000441 | BT7: 0.011931 | BU7: -0.010316 | BV7: 0.030169 | BW7: 0.000873 | BX7: 0.035963 | BY7: 0.012815 | BZ7: 145.03849 | CA7: 145.03849 | CB7: 145.03849 | CC7: 145.03849 | CD7: 145.03849 | CE7: 145.03849 | CF7: 129.777 | CG7: 129.777 | CH7: 129.777 | CI7: 115.62287 | CJ7: 115.62287 | CK7: 115.62287 | CL7: 107.0138 | CM7: 107.0138 | CN7: 107.0138 | CO7: 80.763208 | CP7: 81.786291 | CQ7: 98.739476 | CR7: 78.985161 | CS7: 72.365781 | CT7: 65.971703 | CU7: 62.791985 | CV7: 55.216135 | CW7: 57.4505 | CX7: 49.97717 | CY7: 46022 | CZ7: 46022 | DA7: 46022 | DB7: 46022 | DC7: 46022 | DD7: 46022 | DE7: 45930 | DF7: 45930 | DG7: 45930 | DH7: 45838 | DI7: 45838 | DJ7: 45838 | DK7: 45747 | DL7: 45747 | DM7: 45747 | DN7: 45716 | DO7: 45688 | DP7: 45657 | DQ7: 45626 | DR7: 45596 | DS7: 45565 | DT7: 45535 | DU7: 45504 | DV7: 45473 | DW7: 45443 | DX7: Shareholder Report | DY7: Shareholder Report | DZ7: Shareholder Report | EA7: Shareholder Report | EB7: Shareholder Report | EC7: Shareholder Report | ED7: Shareholder Report | EE7: Shareholder Report | EF7: Shareholder Report | EG7: Shareholder Report | EH7: Shareholder Report | EI7: Shareholder Report | EJ7: Shareholder Report | EK7: Shareholder Report | EL7: Shareholder Report | EM7: Aggregate MFs | EN7: Aggregate MFs | EO7: Aggregate MFs | EP7: Aggregate MFs | EQ7: Aggregate MFs | ER7: Aggregate MFs | ES7: Aggregate MFs | ET7: Aggregate MFs | EU7: Aggregate MFs | EV7: Aggregate MFs | EW7: Investment Managers | EX7: Investment Advisor | EY7: 43320.911 | EZ7: Growth | FA7: Low | FB7: Low | FC7: Low | FD7: Moderate | FE7: Moderate | FF7: Moderate | FG7: Moderate | FH7: Moderate | FI7: Moderate | FJ7: Moderate | FK7: Moderate | FL7: Moderate | FM7: Moderate | FN7: Moderate | FO7: Moderate | FP7: Moderate | FQ7: Moderate | FR7: Moderate | FS7: Moderate | FT7: Moderate | FU7: Moderate | FV7: Moderate | FW7: Moderate | FX7: Moderate | FY7: Moderate | FZ7: Mumbai | GA7: India
A8: 6 | B8: Classic Fintrex Pvt. Ltd. | C8: 0.019234 | D8: 0.019239 | E8: 0.019239 | F8: 0.01924 | G8: 0.01924 | H8: 0.01924 | I8: 0.01924 | J8: 0.019242 | K8: 0.019242 | L8: 0.019244 | M8: 0.019244 | N8: 0.01925 | O8: 0.01925 | P8: 0.019252 | Q8: 0.019252 | R8: 0.019253 | S8: 0.019253 | T8: 0.019255 | U8: 0.019255 | V8: 0.019257 | W8: 0.019259 | X8: 0.019259 | Y8: 0.019259 | Z8: 0.019266 | AA8: 0.019266 | AB8: 2.5761 | AC8: 2.5761 | AD8: 2.5761 | AE8: 2.5761 | AF8: 2.5761 | AG8: 2.5761 | AH8: 2.5761 | AI8: 2.5761 | AJ8: 2.5761 | AK8: 2.5761 | AL8: 2.5761 | AM8: 2.5761 | AN8: 2.5761 | AO8: 2.5761 | AP8: 2.5761 | AQ8: 2.5761 | AR8: 2.5761 | AS8: 2.5761 | AT8: 2.5761 | AU8: 2.5761 | AV8: 2.5761 | AW8: 2.5761 | AX8: 2.5761 | AY8: 2.5761 | AZ8: 2.5761 | BA8: 0 | BB8: 0 | BC8: 0 | BD8: 0 | BE8: 0 | BF8: 0 | BG8: 0 | BH8: 0 | BI8: 0 | BJ8: 0 | BK8: 0 | BL8: 0 | BM8: 0 | BN8: 0 | BO8: 0 | BP8: 0 | BQ8: 0 | BR8: 0 | BS8: 0 | BT8: 0 | BU8: 0 | BV8: 0 | BW8: 0 | BX8: 0 | BY8: 0 | BZ8: 94.675241 | CA8: 94.675241 | CB8: 94.675241 | CC8: 94.675241 | CD8: 94.675241 | CE8: 94.675241 | CF8: 83.897413 | CG8: 83.897413 | CH8: 83.897413 | CI8: 78.911153 | CJ8: 78.911153 | CK8: 78.911153 | CL8: 73.0642 | CM8: 73.0642 | CN8: 73.0642 | CO8: 78.539193 | CP8: 78.539193 | CQ8: 78.539193 | CR8: 62.913065 | CS8: 62.913065 | CT8: 62.913065 | CU8: 55.210531 | CV8: 55.210531 | CW8: 55.210531 | CX8: 53.39832 | CY8: 46022 | CZ8: 46022 | DA8: 46022 | DB8: 46022 | DC8: 46022 | DD8: 46022 | DE8: 45930 | DF8: 45930 | DG8: 45930 | DH8: 45838 | DI8: 45838 | DJ8: 45838 | DK8: 45747 | DL8: 45747 | DM8: 45747 | DN8: 45657 | DO8: 45657 | DP8: 45657 | DQ8: 45565 | DR8: 45565 | DS8: 45565 | DT8: 45473 | DU8: 45473 | DV8: 45473 | DW8: 45382 | DX8: Shareholder Report | DY8: Shareholder Report | DZ8: Shareholder Report | EA8: Shareholder Report | EB8: Shareholder Report | EC8: Shareholder Report | ED8: Shareholder Report | EE8: Shareholder Report | EF8: Shareholder Report | EG8: Shareholder Report | EH8: Shareholder Report | EI8: Shareholder Report | EJ8: Shareholder Report | EK8: Shareholder Report | EL8: Shareholder Report | EM8: Shareholder Report | EN8: Shareholder Report | EO8: Shareholder Report | EP8: Shareholder Report | EQ8: Shareholder Report | ER8: Shareholder Report | ES8: Shareholder Report | ET8: Shareholder Report | EU8: Shareholder Report | EV8: Shareholder Report | EW8: Strategic Entities | EX8: Corporation | EY8: 94.675241 | FA8: Low | FB8: Low | FC8: Low | FD8: Low | FE8: Low | FF8: Low | FG8: Low | FH8: Low | FI8: Low | FJ8: Low | FK8: Low | FL8: Low | FM8: Low | FN8: Low | FO8: Low | FP8: Low | FQ8: Low | FR8: Low | FS8: Low | FT8: Low | FU8: Low | FV8: Low | FW8: Low | FX8: Low | FY8: Low | FZ8: Kolkata | GA8: India
A9: 7 | B9: Vanguard Capital Management, LLC | C9: 0.018844 | D9: 0.018849 | E9: 0.018737 | F9: 0.017751 | G9: 0.01762 | H9: 0.017527 | I9: 0.017443 | J9: 0.01736 | K9: 0.01732 | L9: 0.017358 | M9: 0.017358 | N9: 0.017364 | O9: 0.018556 | P9: 0.018558 | Q9: 0.018593 | R9: 0.018515 | S9: 0.018459 | T9: 0.01843 | U9: 0.018668 | V9: 0.018599 | W9: 0.018558 | X9: 0.018558 | Y9: 0.018547 | Z9: 0.018534 | AA9: 0.018534 | AB9: 2.523786 | AC9: 2.523786 | AD9: 2.508878 | AE9: 2.376755 | AF9: 2.359179 | AG9: 2.346808 | AH9: 2.335562 | AI9: 2.32407 | AJ9: 2.318795 | AK9: 2.323738 | AL9: 2.323738 | AM9: 2.323738 | AN9: 2.483209 | AO9: 2.483209 | AP9: 2.487857 | AQ9: 2.477422 | AR9: 2.469842 | AS9: 2.465772 | AT9: 2.497572 | AU9: 2.488077 | AV9: 2.482427 | AW9: 2.482427 | AX9: 2.480884 | AY9: 2.478292 | AZ9: 2.478292 | BA9: 0 | BB9: 0.014908 | BC9: 0.132123 | BD9: 0.017576 | BE9: 0.012371 | BF9: 0.011246 | BG9: 0.011492 | BH9: 0.005275 | BI9: -0.004943 | BJ9: 0 | BK9: 0 | BL9: -0.159471 | BM9: 0 | BN9: -0.004648 | BO9: 0.010435 | BP9: 0.00758 | BQ9: 0.00407 | BR9: -0.0318 | BS9: 0.009495 | BT9: 0.00565 | BU9: 0 | BV9: 0.001543 | BW9: 0.002592 | BX9: 0 | BY9: 0 | BZ9: 91.082466 | CA9: 91.082466 | CB9: 69.6012 | CC9: 69.220674 | CD9: 72.697889 | CE9: 86.248443 | CF9: 83.862739 | CG9: 82.137861 | CH9: 75.517605 | CI9: 75.701084 | CJ9: 72.48593 | CK9: 71.180795 | CL9: 73.654972 | CM9: 71.634339 | CN9: 70.561423 | CO9: 58.80934 | CP9: 62.167702 | CQ9: 75.175553 | CR9: 72.694148 | CS9: 66.359572 | CT9: 60.625399 | CU9: 57.483842 | CV9: 51.085358 | CW9: 53.114327 | CX9: 46.833373 | CY9: 46142 | CZ9: 46142 | DA9: 46112 | DB9: 46081 | DC9: 46053 | DD9: 46022 | DE9: 45991 | DF9: 45961 | DG9: 45930 | DH9: 45900 | DI9: 45869 | DJ9: 45838 | DK9: 45808 | DL9: 45777 | DM9: 45747 | DN9: 45716 | DO9: 45688 | DP9: 45657 | DQ9: 45626 | DR9: 45596 | DS9: 45565 | DT9: 45535 | DU9: 45504 | DV9: 45473 | DW9: 45443 | DX9: Aggregate MFs | DY9: Aggregate MFs | DZ9: Aggregate MFs | EA9: Aggregate MFs | EB9: Aggregate MFs | EC9: Aggregate MFs | ED9: Aggregate MFs | EE9: Aggregate MFs | EF9: Aggregate MFs | EG9: Aggregate MFs | EH9: Aggregate MFs | EI9: Aggregate MFs | EJ9: Aggregate MFs | EK9: Aggregate MFs | EL9: Aggregate MFs | EM9: Aggregate MFs | EN9: Aggregate MFs | EO9: Aggregate MFs | EP9: Aggregate MFs | EQ9: Aggregate MFs | ER9: Aggregate MFs | ES9: Aggregate MFs | ET9: Aggregate MFs | EU9: Aggregate MFs | EV9: Aggregate MFs | EW9: Investment Managers | EX9: Investment Advisor | EY9: 6105646.3 | EZ9: Index | FZ9: Malvern | GA9: United States
A10: 8 | B10: HSBC Global Asset Management (India) Private Limited | C10: 0.018104 | D10: 0.018108 | E10: 0.018108 | F10: 0.018109 | G10: 0.018109 | H10: 0.018109 | I10: 0.020473 | J10: 0.020475 | K10: 0.020475 | L10: 0.018724 | M10: 0.018724 | N10: 0.01873 | O10: 0.018917 | P10: 0.018919 | Q10: 0.018919 | R10: 0.012093 | S10: 0.012093 | T10: 0.012094 | U10: 0.010153 | V10: 0.009773 | W10: 0.009774 | X10: 0.00913 | Y10: 0.009002 | Z10: 0.009463 | AA10: 0.008891 | AB10: 2.42467 | AC10: 2.42467 | AD10: 2.42467 | AE10: 2.42467 | AF10: 2.42467 | AG10: 2.42467 | AH10: 2.741203 | AI10: 2.741203 | AJ10: 2.741203 | AK10: 2.506502 | AL10: 2.506502 | AM10: 2.506502 | AN10: 2.531502 | AO10: 2.531502 | AP10: 2.531502 | AQ10: 1.618015 | AR10: 1.618015 | AS10: 1.618015 | AT10: 1.358303 | AU10: 1.307356 | AV10: 1.307356 | AW10: 1.221194 | AX10: 1.204076 | AY10: 1.265323 | AZ10: 1.188823 | BA10: 0 | BB10: 0 | BC10: 0 | BD10: 0 | BE10: 0 | BF10: -0.316533 | BG10: 0 | BH10: 0 | BI10: 0.234701 | BJ10: 0 | BK10: 0 | BL10: -0.025 | BM10: 0 | BN10: 0 | BO10: 0.913487 | BP10: 0 | BQ10: 0 | BR10: 0.259712 | BS10: 0.050947 | BT10: 0 | BU10: 0.086162 | BV10: 0.017118 | BW10: -0.061247 | BX10: 0.0765 | BY10: 0.155423 | BZ10: 89.109979 | CA10: 89.109979 | CB10: 89.109979 | CC10: 89.109979 | CD10: 89.109979 | CE10: 89.109979 | CF10: 89.274423 | CG10: 89.274423 | CH10: 89.274423 | CI10: 76.779226 | CJ10: 76.779226 | CK10: 76.779226 | CL10: 71.799297 | CM10: 71.799297 | CN10: 71.799297 | CO10: 49.329449 | CP10: 49.329449 | CQ10: 49.329449 | CR10: 39.534668 | CS10: 34.868529 | CT10: 31.92802 | CU10: 28.278343 | CV10: 24.793845 | CW10: 27.118185 | CX10: 22.465711 | CY10: 46022 | CZ10: 46022 | DA10: 46022 | DB10: 46022 | DC10: 46022 | DD10: 46022 | DE10: 45930 | DF10: 45930 | DG10: 45930 | DH10: 45838 | DI10: 45838 | DJ10: 45838 | DK10: 45747 | DL10: 45747 | DM10: 45747 | DN10: 45657 | DO10: 45657 | DP10: 45657 | DQ10: 45626 | DR10: 45596 | DS10: 45565 | DT10: 45535 | DU10: 45504 | DV10: 45473 | DW10: 45443 | DX10: Shareholder Report | DY10: Shareholder Report | DZ10: Shareholder Report | EA10: Shareholder Report | EB10: Shareholder Report | EC10: Shareholder Report | ED10: Shareholder Report | EE10: Shareholder Report | EF10: Shareholder Report | EG10: Shareholder Report | EH10: Shareholder Report | EI10: Shareholder Report | EJ10: Shareholder Report | EK10: Shareholder Report | EL10: Shareholder Report | EM10: Shareholder Report | EN10: Shareholder Report | EO10: Shareholder Report | EP10: Aggregate MFs | EQ10: Aggregate MFs | ER10: Aggregate MFs | ES10: Aggregate MFs | ET10: Aggregate MFs | EU10: Aggregate MFs | EV10: Aggregate MFs | EW10: Investment Managers | EX10: Investment Advisor | EY10: 9607.0922 | EZ10: GARP | FA10: Moderate | FB10: Moderate | FC10: Low | FD10: Low | FE10: Moderate | FF10: Moderate | FG10: Moderate | FH10: Low | FI10: Low | FJ10: Low | FK10: Moderate | FL10: Low | FM10: Moderate | FN10: Moderate | FO10: Moderate | FP10: Moderate | FQ10: Moderate | FR10: Moderate | FS10: Moderate | FT10: Moderate | FU10: Moderate | FV10: Moderate | FW10: Moderate | FX10: Moderate | FY10: Moderate | FZ10: Mumbai | GA10: India
A11: 9 | B11: Aditya Birla Sun Life AMC Limited | C11: 0.017646 | D11: 0.01765 | E11: 0.01765 | F11: 0.017651 | G11: 0.017651 | H11: 0.017651 | I11: 0.019944 | J11: 0.019946 | K11: 0.019946 | L11: 0.023361 | M11: 0.023361 | N11: 0.023369 | O11: 0.026111 | P11: 0.026114 | Q11: 0.026114 | R11: 0.026105 | S11: 0.026019 | T11: 0.026948 | U11: 0.029787 | V11: 0.032503 | W11: 0.033865 | X11: 0.035225 | Y11: 0.035018 | Z11: 0.035037 | AA11: 0.035002 | AB11: 2.363299 | AC11: 2.363299 | AD11: 2.363299 | AE11: 2.363299 | AF11: 2.363299 | AG11: 2.363299 | AH11: 2.670306 | AI11: 2.670306 | AJ11: 2.670306 | AK11: 3.127343 | AL11: 3.127343 | AM11: 3.127343 | AN11: 3.494217 | AO11: 3.494217 | AP11: 3.494217 | AQ11: 3.49296 | AR11: 3.481408 | AS11: 3.605296 | AT11: 3.985128 | AU11: 4.348214 | AV11: 4.529856 | AW11: 4.711748 | AX11: 4.684117 | AY11: 4.68501 | AZ11: 4.680251 | BA11: 0 | BB11: 0 | BC11: 0 | BD11: 0 | BE11: 0 | BF11: -0.307007 | BG11: 0 | BH11: 0 | BI11: -0.457037 | BJ11: 0 | BK11: 0 | BL11: -0.366874 | BM11: 0 | BN11: 0 | BO11: 0.001257 | BP11: 0.011552 | BQ11: -0.123888 | BR11: -0.379832 | BS11: -0.363086 | BT11: -0.181642 | BU11: -0.181892 | BV11: 0.027631 | BW11: -0.000893 | BX11: 0.004759 | BY11: 0.00078 | BZ11: 86.85451 | CA11: 86.85451 | CB11: 86.85451 | CC11: 86.85451 | CD11: 86.85451 | CE11: 86.85451 | CF11: 86.965477 | CG11: 86.965477 | CH11: 86.965477 | CI11: 95.796841 | CJ11: 95.796841 | CK11: 95.796841 | CL11: 99.104138 | CM11: 99.104138 | CN11: 99.104138 | CO11: 82.916303 | CP11: 87.629547 | CQ11: 109.91694 | CR11: 115.99084 | CS11: 115.97134 | CT11: 110.62735 | CU11: 109.10668 | CV11: 96.453439 | CW11: 100.40833 | CX11: 88.444761 | CY11: 46022 | CZ11: 46022 | DA11: 46022 | DB11: 46022 | DC11: 46022 | DD11: 46022 | DE11: 45930 | DF11: 45930 | DG11: 45930 | DH11: 45838 | DI11: 45838 | DJ11: 45838 | DK11: 45747 | DL11: 45747 | DM11: 45747 | DN11: 45716 | DO11: 45688 | DP11: 45657 | DQ11: 45626 | DR11: 45596 | DS11: 45565 | DT11: 45535 | DU11: 45504 | DV11: 45473 | DW11: 45443 | DX11: Shareholder Report | DY11: Shareholder Report | DZ11: Shareholder Report | EA11: Shareholder Report | EB11: Shareholder Report | EC11: Shareholder Report | ED11: Shareholder Report | EE11: Shareholder Report | EF11: Shareholder Report | EG11: Shareholder Report | EH11: Shareholder Report | EI11: Shareholder Report | EJ11: Shareholder Report | EK11: Shareholder Report | EL11: Shareholder Report | EM11: Aggregate MFs | EN11: Aggregate MFs | EO11: Aggregate MFs | EP11: Aggregate MFs | EQ11: Aggregate MFs | ER11: Aggregate MFs | ES11: Aggregate MFs | ET11: Aggregate MFs | EU11: Aggregate MFs | EV11: Aggregate MFs | EW11: Investment Managers | EX11: Investment Advisor | EY11: 34858.816 | EZ11: Core Growth | FA11: Moderate | FB11: Moderate | FC11: Moderate | FD11: Moderate | FE11: Moderate | FF11: Moderate | FG11: Low | FH11: Low | FI11: Low | FJ11: Low | FK11: Low | FL11: Low | FM11: Low | FN11: Low | FO11: Low | FP11: Low | FQ11: Low | FR11: Low | FS11: Low | FT11: Low | FU11: Low | FV11: Low | FW11: Low | FX11: Low | FY11: Low | FZ11: Mumbai | GA11: India
A12: 10 | B12: TIMF Holdings | C12: 0.016473 | D12: 0.016477 | E12: 0.016477 | F12: 0.016477 | G12: 0.016477 | H12: 0.016477 | I12: 0.019175 | J12: 0.019177 | K12: 0.019177 | L12: 0.023422 | M12: 0.023422 | N12: 0.02343 | O12: 0.023972 | P12: 0.023975 | Q12: 0.023975 | R12: 0.023976 | S12: 0.023976 | T12: 0.023979 | U12: 0.023979 | V12: 0.023981 | W12: 0.023983 | X12: 0.024221 | Y12: 0.024221 | Z12: 0.024229 | AA12: 0.026099 | AB12: 2.206226 | AC12: 2.206226 | AD12: 2.206226 | AE12: 2.206226 | AF12: 2.206226 | AG12: 2.206226 | AH12: 2.567347 | AI12: 2.567347 | AJ12: 2.567347 | AK12: 3.135466 | AL12: 3.135466 | AM12: 3.135466 | AN12: 3.208082 | AO12: 3.208082 | AP12: 3.208082 | AQ12: 3.208082 | AR12: 3.208082 | AS12: 3.208082 | AT12: 3.208082 | AU12: 3.208082 | AV12: 3.208082 | AW12: 3.239819 | AX12: 3.239819 | AY12: 3.239819 | AZ12: 3.489819 | BA12: 0 | BB12: 0 | BC12: 0 | BD12: 0 | BE12: 0 | BF12: -0.361121 | BG12: 0 | BH12: 0 | BI12: -0.568119 | BJ12: 0 | BK12: 0 | BL12: -0.072616 | BM12: 0 | BN12: 0 | BO12: 0 | BP12: 0 | BQ12: 0 | BR12: 0 | BS12: 0 | BT12: 0 | BU12: -0.031737 | BV12: 0 | BW12: 0 | BX12: -0.25 | BY12: 0 | BZ12: 81.08186 | CA12: 81.08186 | CB12: 81.08186 | CC12: 81.08186 | CD12: 81.08186 | CE12: 81.08186 | CF12: 83.612349 | CG12: 83.612349 | CH12: 83.612349 | CI12: 96.045665 | CJ12: 96.045665 | CK12: 96.045665 | CL12: 90.988683 | CM12: 90.988683 | CN12: 90.988683 | CO12: 97.806829 | CP12: 97.806829 | CQ12: 97.806829 | CR12: 78.347219 | CS12: 78.347219 | CT12: 78.347219 | CU12: 69.435243 | CV12: 69.435243 | CW12: 69.435243 | CX12: 72.338214 | CY12: 46022 | CZ12: 46022 | DA12: 46022 | DB12: 46022 | DC12: 46022 | DD12: 46022 | DE12: 45930 | DF12: 45930 | DG12: 45930 | DH12: 45838 | DI12: 45838 | DJ12: 45838 | DK12: 45747 | DL12: 45747 | DM12: 45747 | DN12: 45657 | DO12: 45657 | DP12: 45657 | DQ12: 45565 | DR12: 45565 | DS12: 45565 | DT12: 45473 | DU12: 45473 | DV12: 45473 | DW12: 45382 | DX12: Shareholder Report | DY12: Shareholder Report | DZ12: Shareholder Report | EA12: Shareholder Report | EB12: Shareholder Report | EC12: Shareholder Report | ED12: Shareholder Report | EE12: Shareholder Report | EF12: Shareholder Report | EG12: Shareholder Report | EH12: Shareholder Report | EI12: Shareholder Report | EJ12: Shareholder Report | EK12: Shareholder Report | EL12: Shareholder Report | EM12: Shareholder Report | EN12: Shareholder Report | EO12: Shareholder Report | EP12: Shareholder Report | EQ12: Shareholder Report | ER12: Shareholder Report | ES12: Shareholder Report | ET12: Shareholder Report | EU12: Shareholder Report | EV12: Shareholder Report | EW12: Strategic Entities | EX12: Corporation | EY12: 248.02853 | FA12: Low | FB12: Low | FC12: Low | FD12: Low | FE12: Low | FF12: Low | FG12: Low | FH12: Low | FI12: Low | FJ12: Low | FK12: Low | FL12: Low | FM12: Low | FN12: Low | FO12: Low | FP12: Low | FQ12: Low | FR12: Low | FS12: Low | FT12: Low | FU12: Low | FV12: Low | FW12: Low | FX12: Low | FY12: Low | GA12: Mauritius
A13: 11 | B13: Canara Robeco Asset Management Company Ltd. | C13: 0.013626 | D13: 0.01363 | E13: 0.013784 | F13: 0.010243 | G13: 0.009111 | H13: 0.008899 | I13: 0.0087 | J13: 0.008701 | K13: 0.008062 | L13: 0.008012 | M13: 0.007242 | N13: 0.006407 | O13: 0.004855 | P13: 0.004613 | Q13: 0.004613 | R13: 0.004613 | S13: 0.003369 | T13: 0.002292 | AB13: 1.824974 | AC13: 1.824974 | AD13: 1.845657 | AE13: 1.371438 | AF13: 1.21992 | AG13: 1.191536 | AH13: 1.16491 | AI13: 1.16491 | AJ13: 1.07936 | AK13: 1.07256 | AL13: 0.969446 | AM13: 0.857446 | AN13: 0.649734 | AO13: 0.617287 | AP13: 0.617287 | AQ13: 0.617287 | AR13: 0.450835 | AS13: 0.306669 | BA13: 0 | BB13: -0.020683 | BC13: 0.474219 | BD13: 0.151518 | BE13: 0.028384 | BF13: 0.026626 | BG13: 0 | BH13: 0.08555 | BI13: 0.0068 | BJ13: 0.103114 | BK13: 0.112 | BL13: 0.207712 | BM13: 0.032447 | BN13: 0 | BO13: 0 | BP13: 0.166452 | BQ13: 0.144166 | BR13: 0.306669 | BZ13: 65.862609 | CA13: 65.862609 | CB13: 51.202148 | CC13: 39.941796 | CD13: 37.591725 | CE13: 43.790598 | CF13: 41.828281 | CG13: 41.17054 | CH13: 35.152172 | CI13: 34.941097 | CJ13: 30.240584 | CK13: 26.265305 | CL13: 19.271894 | CM13: 17.807179 | CN13: 17.507698 | CO13: 14.653233 | CP13: 11.347842 | CQ13: 9.3496121 | CY13: 46142 | CZ13: 46142 | DA13: 46112 | DB13: 46081 | DC13: 46053 | DD13: 46022 | DE13: 45991 | DF13: 45961 | DG13: 45930 | DH13: 45900 | DI13: 45869 | DJ13: 45838 | DK13: 45808 | DL13: 45777 | DM13: 45747 | DN13: 45716 | DO13: 45688 | DP13: 45657 | DX13: Aggregate MFs | DY13: Aggregate MFs | DZ13: Aggregate MFs | EA13: Aggregate MFs | EB13: Aggregate MFs | EC13: Aggregate MFs | ED13: Aggregate MFs | EE13: Aggregate MFs | EF13: Aggregate MFs | EG13: Aggregate MFs | EH13: Aggregate MFs | EI13: Aggregate MFs | EJ13: Aggregate MFs | EK13: Aggregate MFs | EL13: Aggregate MFs | EM13: Aggregate MFs | EN13: Aggregate MFs | EO13: Aggregate MFs | EW13: Investment Managers | EX13: Investment Advisor | EY13: 11263.419 | EZ13: Growth | FA13: Low | FB13: Low | FC13: Low | FD13: Low | FE13: Low | FF13: Low | FG13: Low | FH13: Low | FI13: Low | FJ13: Low | FK13: Low | FL13: Low | FM13: Low | FN13: Low | FO13: Low | FP13: Low | FQ13: Low | FR13: Low | FZ13: Mumbai | GA13: India
A14: 12 | B14: Investor Education Protection Fund | C14: 0.013063 | D14: 0.013066 | E14: 0.013066 | F14: 0.013066 | G14: 0.013066 | H14: 0.013066 | I14: 0.012929 | J14: 0.012931 | K14: 0.012931 | L14: 0.013109 | M14: 0.013109 | N14: 0.013113 | O14: 0.013159 | P14: 0.01316 | Q14: 0.01316 | R14: 0.013204 | S14: 0.013204 | T14: 0.013206 | U14: 0.012857 | V14: 0.012858 | W14: 0.012859 | X14: 0.012889 | Y14: 0.012889 | Z14: 0.012893 | AA14: 0.012917 | AB14: 1.749508 | AC14: 1.749508 | AD14: 1.749508 | AE14: 1.749508 | AF14: 1.749508 | AG14: 1.749508 | AH14: 1.731143 | AI14: 1.731143 | AJ14: 1.731143 | AK14: 1.754863 | AL14: 1.754863 | AM14: 1.754863 | AN14: 1.760953 | AO14: 1.760953 | AP14: 1.760953 | AQ14: 1.766748 | AR14: 1.766748 | AS14: 1.766748 | AT14: 1.720108 | AU14: 1.720108 | AV14: 1.720108 | AW14: 1.724033 | AX14: 1.724033 | AY14: 1.724033 | AZ14: 1.727183 | BA14: 0 | BB14: 0 | BC14: 0 | BD14: 0 | BE14: 0 | BF14: 0.018365 | BG14: 0 | BH14: 0 | BI14: -0.02372 | BJ14: 0 | BK14: 0 | BL14: -0.00609 | BM14: 0 | BN14: 0 | BO14: -0.005795 | BP14: 0 | BQ14: 0 | BR14: 0.04664 | BS14: 0 | BT14: 0 | BU14: -0.003925 | BV14: 0 | BW14: 0 | BX14: -0.00315 | BY14: 0 | BZ14: 64.296841 | CA14: 64.296841 | CB14: 64.296841 | CC14: 64.296841 | CD14: 64.296841 | CE14: 64.296841 | CF14: 56.379185 | CG14: 56.379185 | CH14: 56.379185 | CI14: 53.755003 | CJ14: 53.755003 | CK14: 53.755003 | CL14: 49.944731 | CM14: 49.944731 | CN14: 49.944731 | CO14: 53.863966 | CP14: 53.863966 | CQ14: 53.863966 | CR14: 42.008178 | CS14: 42.008178 | CT14: 42.008178 | CU14: 36.949178 | CV14: 36.949178 | CW14: 36.949178 | CX14: 35.801666 | CY14: 46022 | CZ14: 46022 | DA14: 46022 | DB14: 46022 | DC14: 46022 | DD14: 46022 | DE14: 45930 | DF14: 45930 | DG14: 45930 | DH14: 45838 | DI14: 45838 | DJ14: 45838 | DK14: 45747 | DL14: 45747 | DM14: 45747 | DN14: 45657 | DO14: 45657 | DP14: 45657 | DQ14: 45565 | DR14: 45565 | DS14: 45565 | DT14: 45473 | DU14: 45473 | DV14: 45473 | DW14: 45382 | DX14: Shareholder Report | DY14: Shareholder Report | DZ14: Shareholder Report | EA14: Shareholder Report | EB14: Shareholder Report | EC14: Shareholder Report | ED14: Shareholder Report | EE14: Shareholder Report | EF14: Shareholder Report | EG14: Shareholder Report | EH14: Shareholder Report | EI14: Shareholder Report | EJ14: Shareholder Report | EK14: Shareholder Report | EL14: Shareholder Report | EM14: Shareholder Report | EN14: Shareholder Report | EO14: Shareholder Report | EP14: Shareholder Report | EQ14: Shareholder Report | ER14: Shareholder Report | ES14: Shareholder Report | ET14: Shareholder Report | EU14: Shareholder Report | EV14: Shareholder Report | EW14: Strategic Entities | EX14: Corporation | EY14: 9985.9213 | FA14: Low | FB14: Low | FC14: Low | FD14: Low | FE14: Low | FF14: Low | FG14: Low | FH14: Low | FI14: Low | FJ14: Low | FK14: Low | FL14: Low | FM14: Low | FN14: Low | FO14: Low | FP14: Low | FQ14: Low | FR14: Low | FS14: Low | FT14: Low | FU14: Low | FV14: Low | FW14: Low | FX14: Low | FY14: Low | FZ14: New Delhi | GA14: India
A15: 13 | B15: Motilal Oswal Asset Management Company Ltd. | C15: 0.011861 | D15: 0.011863 | E15: 0.003905 | F15: 0.002766 | G15: 0.002621 | H15: 0.002979 | I15: 0.002956 | J15: 0.002949 | K15: 0.002815 | L15: 0.003616 | M15: 0.002222 | N15: 0.002437 | O15: 0.002476 | P15: 0.002468 | Q15: 0.002424 | R15: 0.002198 | S15: 0.002434 | T15: 0.002395 | U15: 0.000352 | V15: 0.000341 | W15: 0.000337 | X15: 0.000345 | Y15: 0.000322 | Z15: 0.0003 | AA15: 0.000293 | AB15: 1.588498 | AC15: 1.588498 | AD15: 0.522862 | AE15: 0.370371 | AF15: 0.350987 | AG15: 0.398803 | AH15: 0.395825 | AI15: 0.394794 | AJ15: 0.376855 | AK15: 0.484078 | AL15: 0.297473 | AM15: 0.326133 | AN15: 0.33136 | AO15: 0.330254 | AP15: 0.324316 | AQ15: 0.294064 | AR15: 0.325706 | AS15: 0.320414 | AT15: 0.047097 | AU15: 0.045611 | AV15: 0.045014 | AW15: 0.046186 | AX15: 0.043079 | AY15: 0.040108 | AZ15: 0.039199 | BA15: 0 | BB15: 1.065636 | BC15: 0.152491 | BD15: 0.019384 | BE15: -0.047816 | BF15: 0.002978 | BG15: 0.001031 | BH15: 0.017939 | BI15: -0.107223 | BJ15: 0.186605 | BK15: -0.02866 | BL15: -0.005227 | BM15: 0.001106 | BN15: 0.005938 | BO15: 0.030252 | BP15: -0.031642 | BQ15: 0.005292 | BR15: 0.273317 | BS15: 0.001486 | BT15: 0.000597 | BU15: -0.001172 | BV15: 0.003107 | BW15: 0.002971 | BX15: 0.000909 | BY15: 0.00017 | BZ15: 57.328282 | CA15: 57.328282 | CB15: 14.505218 | CC15: 10.786695 | CD15: 10.815633 | CE15: 14.656562 | CF15: 14.21284 | CG15: 13.952908 | CH15: 12.273266 | CI15: 15.769949 | CJ15: 9.2792763 | CK15: 9.9901134 | CL15: 9.8285371 | CM15: 9.5269979 | CN15: 9.1983576 | CO15: 6.9805265 | CP15: 8.1982547 | CQ15: 9.7686646 | CR15: 1.3708018 | CS15: 1.2164923 | CT15: 1.0993241 | CU15: 1.0694972 | CV15: 0.88706531 | CW15: 0.85958775 | CX15: 0.74076073 | CY15: 46142 | CZ15: 46142 | DA15: 46112 | DB15: 46081 | DC15: 46053 | DD15: 46022 | DE15: 45991 | DF15: 45961 | DG15: 45930 | DH15: 45900 | DI15: 45869 | DJ15: 45838 | DK15: 45808 | DL15: 45777 | DM15: 45747 | DN15: 45716 | DO15: 45688 | DP15: 45657 | DQ15: 45626 | DR15: 45596 | DS15: 45565 | DT15: 45535 | DU15: 45504 | DV15: 45473 | DW15: 45443 | DX15: Aggregate MFs | DY15: Aggregate MFs | DZ15: Aggregate MFs | EA15: Aggregate MFs | EB15: Aggregate MFs | EC15: Aggregate MFs | ED15: Aggregate MFs | EE15: Aggregate MFs | EF15: Aggregate MFs | EG15: Aggregate MFs | EH15: Aggregate MFs | EI15: Aggregate MFs | EJ15: Aggregate MFs | EK15: Aggregate MFs | EL15: Aggregate MFs | EM15: Aggregate MFs | EN15: Aggregate MFs | EO15: Aggregate MFs | EP15: Aggregate MFs | EQ15: Aggregate MFs | ER15: Aggregate MFs | ES15: Aggregate MFs | ET15: Aggregate MFs | EU15: Aggregate MFs | EV15: Aggregate MFs | EW15: Investment Managers | EX15: Investment Advisor | EY15: 14769.322 | EZ15: GARP | FA15: Moderate | FB15: Low | FC15: Low | FD15: Moderate | FE15: Moderate | FF15: Moderate | FG15: Moderate | FH15: Moderate | FI15: Moderate | FJ15: Moderate | FK15: Moderate | FL15: Moderate | FM15: Moderate | FN15: Moderate | FO15: Moderate | FP15: Moderate | FQ15: Moderate | FR15: Moderate | FS15: Moderate | FT15: Moderate | FU15: Moderate | FV15: Moderate | FW15: Moderate | FX15: Moderate | FY15: Moderate | FZ15: Mumbai | GA15: India
